Workbook
Name \C: #REF!
Name \M: #REF!
Name \S: #REF!
Name \X: #REF!
Name ____1: #REF!
Name ____17.2: #REF!
Name ____17.3: #REF!
Name ____17.4: #REF!
Name ____17.5: #REF!
Name ____17.6: #REF!
Name ____17.7: #REF!
Name ____17.8: #REF!
Name ____18.2: #REF!
Name ____18.3: #REF!
Name ____18.4: #REF!
Name ____2.2: #REF!
Name ____2.3: #REF!
Name ____20.1: #REF!
Name ____3.1: #REF!
Name ____3.2: #REF!
Name ____4: #REF!
Name ____5: #REF!
Name ____6.4: #REF!
Name ___1: #REF!
Name ___17.2: #REF!
Name ___17.3: #REF!
Name ___17.4: #REF!
Name ___17.5: #REF!
Name ___17.6: #REF!
Name ___17.7: #REF!
Name ___17.8: #REF!
Name ___18.2: #REF!
Name ___18.3: #REF!
Name ___18.4: #REF!
Name ___2.2: #REF!
Name ___2.3: #REF!
Name ___20.1: #REF!
Name ___3.1: #REF!
Name ___3.2: #REF!
Name ___4: #REF!
Name ___5: #REF!
Name ___6.4: #REF!
Name __1: #REF!
Name __17.2: #REF!
Name __17.3: #REF!
Name __17.4: #REF!
Name __17.5: #REF!
Name __17.6: #REF!
Name __17.7: #REF!
Name __17.8: #REF!
Name __18.2: #REF!
Name __18.3: #REF!
Name __18.4: #REF!
Name __2.2: #REF!
Name __2.3: #REF!
Name __20.1: #REF!
Name __3.1: #REF!
Name __3.2: #REF!
Name __4: #REF!
Name __5: #REF!

Sheet EV Calculation and LTI Payout
B1: Linking Enterprise Value Creation to CEO LTI Payout
B4: Select Active Scenario | C4: 2 | D4: =IF($C$4=1,$D8,IF($C$4=2,$E8,IF($C$4=3,$F8))) -> B = Linear Regression
B6: Step 1: Replace data highlighted in purple font in this worksheet. Then choose the active scenario drop down menu to get started.
C8: Assumption | D8: A = Aggressive (+10%) | E8: B = Linear Regression | F8: C = Base Forecast | G8: D= Conservative (–25%) | H8: E= Custom (% growth per year) | L8: A
B9: Revenue Growth % | C9: =IF($C$4=1,$D9,IF($C$4=2,$E9,IF($C$4=3,$F9,IF($C$4=4,G9,IF($C$4=5,H9))))) -> 0.12837621 | D9: ='[13]Forecasting Revenue'!G22 -> 0.16047027 | E9: ='[13]Forecasting Revenue'!G23 -> 0.12837621 | F9: ='[13]Forecasting Revenue'!G24 -> 0.097 | G9: ='[13]Forecasting Revenue'!G25 -> 0.07275 | H9: ='[13]LTI Performance Curve Payout'!D20 -> 0.07 | L9: B
B10: Gross Margin % | C10: =IF($C$4=1,$D10,IF($C$4=2,$E10,IF($C$4=3,$F10,IF($C$4=4,G10,IF($C$4=5,H10))))) -> 0.36 | D10: 0.4 | E10: 0.36 | F10: 0.4 | G10: 0.34 | H10: =IF(H9>=D9,D10+(H9-D9)*(B10-D10)/(B9-D9),D10+(H9-D9)*(F10-D10)/(F9-D9)) -> 0.4 | L10: C
B11: SG&A % | C11: =IF($C$4=1,$D11,IF($C$4=2,$E11,IF($C$4=3,$F11,IF($C$4=4,G11,IF($C$4=5,H11))))) -> 0.2 | D11: 0.16 | E11: 0.2 | F11: 0.16 | G11: 0.22 | H11: =IF(H9>=D9,D11+(H9-D9)*(B11-D11)/(B9-D9),D11+(H9-D9)*(F11-D11)/(F9-D9)) -> 0.16 | L11: D
B12: Terminal Growth % | C12: =IF($C$4=1,$D12,IF($C$4=2,$E12,IF($C$4=3,$F12,IF($C$4=4,G12,IF($C$4=5,H12))))) -> 0.04 | D12: 0.05 | E12: 0.04 | F12: 0.03 | G12: 0.02 | H12: =IF(H9>=D9,D12+(H9-D9)*(B12-D12)/(B9-D9),D12+(H9-D9)*(F12-D12)/(F9-D9)) -> 0.021492079 | L12: E
B13: Discount Rate % | C13: =IF($C$4=1,$D13,IF($C$4=2,$E13,IF($C$4=3,$F13,IF($C$4=4,G13,IF($C$4=5,H13))))) -> 0.13 | D13: 0.15 | E13: 0.13 | F13: 0.11 | G13: 0.09 | H13: =IF(H9>=D9,D13+(H9-D9)*(B13-D13)/(B9-D9),D13+(H9-D9)*(F13-D13)/(F9-D9)) -> 0.092984158
B14: D&A $ | C14: =IF($C$4=1,$D14,IF($C$4=2,$E14,IF($C$4=3,$F14,IF($C$4=4,G14,IF($C$4=5,H14))))) -> 35000000 | D14: 35000000 | E14: 35000000 | F14: 35000000 | G14: 35000000 | H14: =IF(H9>=D9,D14+(H9-D9)*(B14-D14)/(B9-D9),D14+(H9-D9)*(F14-D14)/(F9-D9)) -> 35000000
B15: Interest Expense $ | C15: =IF($C$4=1,$D15,IF($C$4=2,$E15,IF($C$4=3,$F15,IF($C$4=4,G15,IF($C$4=5,H15))))) -> 500000 | D15: 500000 | E15: 500000 | F15: 500000 | G15: 500000 | H15: =IF(H9>=D9,D15+(H9-D9)*(B15-D15)/(B9-D9),D15+(H9-D9)*(F15-D15)/(F9-D9)) -> 500000
B16: Income Tax % | C16: =IF($C$4=1,$D16,IF($C$4=2,$E16,IF($C$4=3,$F16,IF($C$4=4,G16,IF($C$4=5,H16))))) -> 0.27 | D16: 0.27 | E16: 0.27 | F16: 0.27 | G16: 0.28 | H16: =IF(H9>=D9,D16+(H9-D9)*(B16-D16)/(B9-D9),D16+(H9-D9)*(F16-D16)/(F9-D9)) -> 0.27
B17: Capex % | C17: =IF($C$4=1,$D17,IF($C$4=2,$E17,IF($C$4=3,$F17,IF($C$4=4,G17,IF($C$4=5,H17))))) -> 0.08 | D17: 0.055 | E17: 0.08 | F17: 0.055 | G17: 0.085 | H17: =IF(H9>=D9,D17+(H9-D9)*(B17-D17)/(B9-D9),D17+(H9-D9)*(F17-D17)/(F9-D9)) -> 0.055
B18: Participation Rate % | C18: =IF($C$4=1,$D18,IF($C$4=2,$E18,IF($C$4=3,$F18,IF($C$4=4,G18,IF($C$4=5,H18))))) -> 0.04 | D18: 0.05 | E18: 0.04 | F18: 0.05 | G18: 0.03 | H18: =IF(H9>=D9,D18+(H9-D9)*(B18-D18)/(B9-D9),D18+(H9-D9)*(F18-D18)/(F9-D9)) -> 0.05
B19: Change in Working Capital % | C19: =IF($C$4=1,$D19,IF($C$4=2,$E19,IF($C$4=3,$F19,IF($C$4=4,G19,IF($C$4=5,H19))))) -> 0.03 | D19: 0.01 | E19: 0.03 | F19: 0.01 | G19: 0.04 | H19: =IF(H9>=D9,D19+(H9-D9)*(B19-D19)/(B9-D9),D19+(H9-D9)*(F19-D19)/(F9-D9)) -> 0.01
B23: Step 2: Review Income Statement 2022-2024 to Forecast for 2025-2029
B24: To accurately forecast Enterprise Value Creation from 2025–2029, we begin by reviewing at least the last three years of the income statement, cash flow statement, and balance sheet to identify historical trends and validate future projections. This allows us to build scenario-driven assumptions—conservative, moderate, or aggressive—for key drivers such as revenue growth, COGS, gross profit margin, SG&A, D&A, interest expense, income tax rate, CapEx, cash, debt, and shares outstanding.- These inputs feed directly into the next step: calculating Earnings Before Interests, Taxees, Depreciation, Amorizzation (EBITDA), Terminal Values (TV), and Free Cash Flow (FCF), which are essential for estimating the company’s Enterprise Value (EV) gain.
B27: Income Statement | C27: Historical | F27: Projection
C28: 2022 | D28: 2023 | E28: 2024 | F28: 2025 | G28: 2026 | H28: 2027 | I28: 2028 | J28: 2029
B29: Revenue | C29: 50265317 | D29: 62402646 | E29: 61988811 | F29: =E29*(1+$C$9) -> 69946700 | G29: =F29*(1+$C$9) -> 78926192 | H29: =G29*(1+$C$9) -> 89058438 | I29: =H29*(1+$C$9) -> 1.0049142e+08 | J29: =I29*(1+$C$9) -> 1.1339213e+08
B30: COGS | C30: 33505385 | D30: 38814255 | E30: 37392078 | F30: =E29*(1-$C$10) -> 39672839 | G30: =F29*(1-$C$10) -> 44765888 | H30: =G29*(1-$C$10) -> 50512763 | I30: =H29*(1-$C$10) -> 56997400 | J30: =I29*(1-$C$10) -> 64314511
B31: Gross Profit Margin $ | C31: =C29-C30 -> 16759932 | D31: =D29-D30 -> 23588391 | E31: =E29-E30 -> 24596733 | F31: =F29-F30 -> 30273861 | G31: =G29-G30 -> 34160304 | H31: =H29-H30 -> 38545675 | I31: =I29-I30 -> 43494023 | J31: =J29-J30 -> 49077621
B32: SG&A | C32: 9132438 | D32: 10150353 | E32: 12389730 | F32: =F29*$C$11 -> 13989340 | G32: =G29*$C$11 -> 15785238 | H32: =H29*$C$11 -> 17811688 | I32: =I29*$C$11 -> 20098285 | J32: =J29*$C$11 -> 22678426
B33: D&A | C33: 2764593 | D33: 3432146 | E33: 3409385 | F33: =$C$14 -> 35000000 | G33: =$C$14 -> 35000000 | H33: =$C$14 -> 35000000 | I33: =$C$14 -> 35000000 | J33: =$C$14 -> 35000000
B34: Interest Expense | C34: 500000 | D34: 500000 | E34: 500000 | F34: =$C$15 -> 500000 | G34: =$C$15 -> 500000 | H34: =$C$15 -> 500000 | I34: =$C$15 -> 500000 | J34: =$C$15 -> 500000
B35: Income Before Income Taxes | C35: =C31-C32-C33-C34 -> 4362901 | D35: =D31-D32-D33-D34 -> 9505892.3 | E35: =E31-E32-E33-E34 -> 8297617.6 | F35: =F31-F32-F33-F34 -> -19215479 | G35: =G31-G32-G33-G34 -> -17124934 | H35: =H31-H32-H33-H34 -> -14766013 | I35: =I31-I32-I33-I34 -> -12104262 | J35: =J31-J32-J33-J34 -> -9100805.6
B36: Income Taxes | C36: 977289.82 | D36: 2548270 | E36: 2216891 | F36: =F33*$C$16 -> 9450000 | G36: =G33*$C$16 -> 9450000 | H36: =H33*$C$16 -> 9450000 | I36: =I33*$C$16 -> 9450000 | J36: =J33*$C$16 -> 9450000
B37: Net income | C37: =C35-C36 -> 3385611.2 | D37: =D35-D36 -> 6957622.3 | E37: =E35-E36 -> 6080726.6 | F37: =F35-F36 -> -28665479 | G37: =G35-G36 -> -26574934 | H37: =H35-H36 -> -24216013 | I37: =I35-I36 -> -21554262 | J37: =J35-J36 -> -18550806
B38: Revenue growth % | C38: (base yr.) | D38: =(D29-C29)/C29 -> 0.24146528 | E38: =(E29-D29)/D29 -> -0.0066316899 | F38: =(F29-E29)/E29 -> 0.12837621 | G38: =(G29-F29)/F29 -> 0.12837621 | H38: =(H29-G29)/G29 -> 0.12837621 | I38: =(I29-H29)/H29 -> 0.12837621 | J38: =(J29-I29)/I29 -> 0.12837621
B39: Gross Margin % | C39: =C31/C29 -> 0.33342935 | D39: =D31/D29 -> 0.37800306 | E39: =E31/E29 -> 0.3967931 | F39: =F31/F29 -> 0.43281328 | G39: =G31/G29 -> 0.43281328 | H39: =H31/H29 -> 0.43281328 | I39: =I31/I29 -> 0.43281328 | J39: =J31/J29 -> 0.43281328
B40: SG&A - % of revenue | C40: =C32/C29 -> 0.18168468 | D40: =D32/D29 -> 0.16265902 | E40: =E32/E29 -> 0.19987043 | F40: =F32/F29 -> 0.2 | G40: =G32/G29 -> 0.2 | H40: =H32/H29 -> 0.2 | I40: =I32/I29 -> 0.2 | J40: =J32/J29 -> 0.2
B41: Income Tax - % of pretax profit | C41: =C36/C35 -> 0.224 | D41: =D36/D35 -> 0.26807268 | E41: =E36/E35 -> 0.26717199 | F41: =F36/F35 -> -0.49179101 | G41: =G36/G35 -> -0.55182694 | H41: =H36/H35 -> -0.6399832 | I41: =I36/I35 -> -0.78071675 | J41: =J36/J35 -> -1.0383696
B42: CapEx | C42: 3518572 | D42: 4368186 | E42: 2800000 | F42: =F29*$C$17 -> 5595736 | G42: =G29*$C$17 -> 6314095.4 | H42: =H29*$C$17 -> 7124675 | I42: =I29*$C$17 -> 8039313.8 | J42: =J29*$C$17 -> 9071370.5
B43: % of revenue | C43: =C42/C29 -> 0.069999996 | D43: =D42/D29 -> 0.070000012 | E43: =E42/E29 -> 0.045169442 | F43: =F42 / F29 -> 0.08 | G43: =G42 / G29 -> 0.08 | H43: =H42 / H29 -> 0.08 | I43: =I42 / I29 -> 0.08 | J43: =J42 / J29 -> 0.08
B44: Cash | C44: 2513266 | D44: 3120132 | E44: 3099441 | F44: =20000 -> 20000 | G44: =20000 -> 20000 | H44: =20000 -> 20000 | I44: =20000 -> 20000 | J44: 20000
B45: Debt | C45: 6500000 | D45: 7000000 | E45: 7500000 | F45: =7500000 -> 7500000 | G45: =7500000 -> 7500000 | H45: =7500000 -> 7500000 | I45: 7500000 | J45: 7500000
B46: Shares Outstanding | C46: 0 | D46: 75000 | E46: 75000 | F46: =0 -> 0 | G46: =0 -> 0 | H46: =0 -> 0 | I46: =0 -> 0 | J46: =0 -> 0
B50: Step 3: Calculate EBITDA, Terminal and Free Cash Flow
B51: Terminal Value (TV) Undiscounted reflects the company's estimated value beyond the forecast period at Future Value (FV), while Terminal Value (TV) Discounted brings that amount back to Present Value (PV) using the Discount Rate (WACC). For FV Terminal Value, we use Gordon Growth Formula. For PV Terminal Value we use the DFC Formula.
F53: 1 | G53: =F53+1 -> 2 | H53: =G53+1 -> 3 | I53: =H53+1 -> 4 | J53: =I53+1 -> 5
...

Sheet DCF and Gordon Growth Model
B1: Gordon Growth, DCF & Enterprise Valuation Analysis
B3: Based on the financial information on the previous tab, value the company based on the following additional assumptions:
B5: WACC / Discount Rate | C5: ='EV Calculation and LTI Payout'!Discount_Rate -> 0.13
B6: Terminal growth rate | C6: ='EV Calculation and LTI Payout'!C12 -> 0.04
B7: Shares outstanding | C7: 26550
C11: 2024 | D11: 2025 | E11: 2026 | F11: 2027 | G11: 2028 | H11: 2029
B12: Revenue | C12: ='EV Calculation and LTI Payout'!E29 -> 61988811 | D12: ='EV Calculation and LTI Payout'!F29 -> 69946700 | E12: ='EV Calculation and LTI Payout'!G29 -> 78926192 | F12: ='EV Calculation and LTI Payout'!H29 -> 89058438 | G12: ='EV Calculation and LTI Payout'!I29 -> 1.0049142e+08 | H12: ='EV Calculation and LTI Payout'!J29 -> 1.1339213e+08
B13: COGS | C13: ='EV Calculation and LTI Payout'!E30 -> 37392078 | D13: ='EV Calculation and LTI Payout'!F30 -> 39672839 | E13: ='EV Calculation and LTI Payout'!G30 -> 44765888 | F13: ='EV Calculation and LTI Payout'!H30 -> 50512763 | G13: ='EV Calculation and LTI Payout'!I30 -> 56997400 | H13: ='EV Calculation and LTI Payout'!J30 -> 64314511
B14: Gross Profit | C14: =C12-C13 -> 24596733 | D14: =D12-D13 -> 30273861 | E14: =E12-E13 -> 34160304 | F14: =F12-F13 -> 38545675 | G14: =G12-G13 -> 43494023 | H14: =H12-H13 -> 49077621
B16: SG&A | C16: ='EV Calculation and LTI Payout'!E32 -> 12389730 | D16: ='EV Calculation and LTI Payout'!F32 -> 13989340 | E16: ='EV Calculation and LTI Payout'!G32 -> 15785238 | F16: ='EV Calculation and LTI Payout'!H32 -> 17811688 | G16: ='EV Calculation and LTI Payout'!I32 -> 20098285 | H16: ='EV Calculation and LTI Payout'!J32 -> 22678426
B18: EBITDA | C18: =C14-C16 -> 12207003 | D18: =D14-D16 -> 16284521 | E18: =E14-E16 -> 18375066 | F18: =F14-F16 -> 20733987 | G18: =G14-G16 -> 23395738 | H18: =H14-H16 -> 26399194
B19: (-) Capex | C19: ='EV Calculation and LTI Payout'!E57 -> 2800000 | D19: ='EV Calculation and LTI Payout'!F57 -> 5595736 | E19: ='EV Calculation and LTI Payout'!G57 -> 6314095.4 | F19: ='EV Calculation and LTI Payout'!H57 -> 7124675 | G19: ='EV Calculation and LTI Payout'!I57 -> 8039313.8 | H19: ='EV Calculation and LTI Payout'!J57 -> 9071370.5
B20: (-) Taxes | C20: ='EV Calculation and LTI Payout'!E58 -> 2216891 | D20: ='EV Calculation and LTI Payout'!F58 -> 9450000 | E20: ='EV Calculation and LTI Payout'!G58 -> 9450000 | F20: ='EV Calculation and LTI Payout'!H58 -> 9450000 | G20: ='EV Calculation and LTI Payout'!H58 -> 9450000 | H20: ='EV Calculation and LTI Payout'!I58 -> 9450000
B21: (-) Change in working capital | C21: ='EV Calculation and LTI Payout'!E59 -> 1859664.3 | D21: ='EV Calculation and LTI Payout'!F59 -> 2098401 | E21: ='EV Calculation and LTI Payout'!G59 -> 2367785.8 | F21: ='EV Calculation and LTI Payout'!H59 -> 2671753.1 | G21: ='EV Calculation and LTI Payout'!I59 -> 3014742.7 | H21: ='EV Calculation and LTI Payout'!J59 -> 3401763.9
B22: Unlevered Free Cash Flow | C22: =C18-C19-C20-C21 -> 5330447.2 | D22: =D18-D19-D20-D21 -> -859616.16 | E22: =E18-E19-E20-E21 -> 243184.78 | F22: =F18-F19-F20-F21 -> 1487559.1 | G22: =G18-G19-G20-G21 -> 2891681.6 | H22: =H18-H19-H20-H21 -> 4476059.9
F23: FV Terminal Value | H23: =H22/(C5-C6) -> 49733999 | J23: Undiscounted Terminal Value (FY), use Gordon Growth Fomrula
F24: PV Terminal Value | H24: =H23/(1+C5)^5 -> 26993622 | J24: Discounted Terminatl Value (PV), use DCF Formula
B26: Discounted FCF | C26: =C22/(1+$C$5)^(C11-2023) -> 4717209.9 | D26: =D22/(1+$C$5)^(D11-C11) -> -760722.27 | E26: =E22/(1+$C$5)^(E11-D11) -> 215207.77 | F26: =F22/(1+$C$5)^(F11-E11) -> 1316424 | G26: =G22/(1+$C$5)^(G11-F11) -> 2559010.2 | H26: =H22/(1+$C$5)^(H11-G11) -> 3961115
H27: =SUM(C26:H26) -> 12008245
H28: =SUM(C26:H26)+H24 -> 39001867
B30: Sensitivity Analysis For Steady Terminal Growth
D32: 🌱 Steady Terminal Growth Rates (used in the Gordon Growth formula)
C33: =H28 -> 39001867 | D33: -0.02 | E33: -0.01 | F33: 0 | G33: 0.01 | H33: 0.02 | I33: 0.03
B34: 📉 Discount Rates | C34: 0.07 | D34: 48141258 | E34: 52573715 | F34: 58272588 | G34: 65871085 | H34: 76508981 | I34: 92465825
C35: =+C34+0.5% -> 0.075 | D35: 45441969 | E35: 49303069 | F35: 54193796 | G35: 60589361 | H35: 69310587 | I35: 81907913
C36: =+C35+0.5% -> 0.08 | D36: 43027494 | E36: 46412306 | F36: 50643321 | G36: 56083198 | H36: 63336368 | I36: 73490805
C37: =+C36+0.5% -> 0.085 | D37: 40856598 | E37: 43840842 | F37: 47527261 | G37: 52196725 | H37: 58302946 | I37: 66629613
C38: =+C37+0.5% -> 0.09 | D38: 38895567 | E38: 41540232 | F38: 44772601 | G38: 48813062 | H38: 54007940 | I38: 60934445
D39: As expected, increasing the discount rate from 7.0% to 9.0% significantly reduces enterprise value. Conversely, increasing the terminal growth rate raises the valuation, as it boosts the terminal value component in the Gordon Growth Model
B42: CEO Payout FY2029
B43: Starting Enterprise Value | C43: =SUM(D26:H26)+H24 -> 34284657
B44: Ending Enterprise Value | C44: =H23 -> 49733999
B45: Value Created | C45: =C44-C43 -> 15449342
B46: Participation Rate: | C46: 0.04
B47: 4 yr LTI Grant Payout: | C47: =C46*C45 -> 617973.69
B49: Pay Elements | C49: 35th P | D49: 50th P | E49: 75th P
B50: Salary | C50: 350000 | D50: 400000 | E50: 450000
B51: AIP Target | C51: 0.25 | D51: 0.3 | E51: 0.4
B52: LTI Value | C52: =C47/4 -> 154493.42 | D52: =C47/4 -> 154493.42 | E52: =C47/4 -> 154493.42
B53: Total Direct Comp | C53: =(C51*C50)+C50+C52 -> 591993.42 | D53: =(D51*D50)+D50+D52 -> 674493.42 | E53: =(E51*E50)+E50+E52 -> 784493.42
