Workbook

Sheet STI Calculator
A1: For Illustration Purposes
B4: AIP Calculation Example 2: Above Target Outcome
B6: Hire Date | C6: 46023
B7: Fiscal Year: | C7: 46022
B8: Base Salary | C8: 350000
B9: AIP Target % | C9: 0.5
B10: AIP Target $ | C10: =C9*C8 -> 175000
B11: Prorated Target: | C11: =IFERROR((((C7-C6)+1)/365)*C10,"") -> 0
B12: Target Total Comp | C12: =C10+C8 -> 525000
N13: FINANCIAL PERFORMANCE Attainment (% of Goal) | Q13: PAY Bonus Award (as % of Target Bonus)
B14: Weight | C14: Financial Measures | D14: Sub-Wgt | E14: Weight on TOTAL | F14: Goal ($000) | G14: Actual ($000) | H14: Attainment % | I14: Payout (% of Target) | K14: Alternate calc | N14: Threshold | O14: Target | P14: Max | Q14: < Threshold | R14: Threshold | S14: Target | T14: Max
B15: 0.8 | C15: Revenue | D15: 0.6 | E15: =B15*D15 -> 0.48 | F15: 74338 | G15: 79000 | H15: =IF(F15=0,"",G15/F15) -> 1.0627136 | I15: =IF(AND(H15>=O15,H15<=P15),1+((H15-1)/(P15-O15))*(T15-S15),IF(AND(H15>=N15,H15<O15),1-((1-H15)/(O15-N15))*(S15-R15),IF(H15>P15,T15,0))) -> 1.2090452 | K15: =I15*D15 -> 0.7254271 | M15: Revenue | N15: 0.85 | O15: 1 | P15: 1.15 | Q15: 0 | R15: 0.5 | S15: 1 | T15: 1.5
C16: EBITDA | D16: =1-D15 -> 0.4 | E16: =B15*D16 -> 0.32 | F16: 14718 | G16: 16000 | H16: =IF(F16=0,"",G16/F16) -> 1.0871042 | I16: =IF(AND(H16>=O16,H16<=P16),1+((H16-1)/(P16-O16))*(T16-S16),IF(AND(H16>=N16,H16<O16),1-((1-H16)/(O16-N16))*(S16-R16),IF(H16>P16,T16,0))) -> 1.4355211 | K16: =I16*D16 -> 0.57420845 | M16: Net Income | N16: 0.9 | O16: 1 | P16: 1.1 | Q16: 0 | R16: 0.5 | S16: 1 | T16: 1.5
K17: =K15+K16 -> 1.2996356
B18: Weight | C18: Strategic Measures | D18: Sub-Wgt | E18: Weight on TOTAL | F18: Goal | G18: Actual % | H18: Attainment % | I18: Payout (% of Target) | N18: STRATEGIC PERFORMANCE | Q18: PAY
B19: =1-B15 -> 0.2 | C19: Objective 1 | D19: 0.4 | E19: =$B$19*D19 -> 0.08 | F19: Ex: Culture Goal | H19: 1.05 | I19: =IF(AND(H19>=O20,H19<=P20),1+((H19-1)/(P20-O20))*(T20-S20),IF(AND(H19>=N20,H19<O20),1-((1-H19)/(O20-N20))*(S20-R20),IF(H19>P20,T20,0))) -> 1.05 | N19: Threshold | O19: Target | P19: Max | Q19: < Threshold | R19: Threshold | S19: Target | T19: Max
C20: Objective 2 | D20: 0.3 | E20: =$B$19*D20 -> 0.06 | F20: Ex: Ops Goal | H20: 1 | I20: =IF(AND(H20>=O21,H20<=P21),1+((H20-1)/(P21-O21))*(T21-S21),IF(AND(H20>=N21,H20<O21),1-((1-H20)/(O21-N21))*(S21-R21),IF(H20>P21,T21,0))) -> 1 | K20: =I19*D19 -> 0.42 | M20: Objective 1 | N20: 0.9 | O20: 1 | P20: 1.1 | Q20: 0 | R20: 0.5 | S20: 1 | T20: 1.1
C21: Objective 3 | D21: 0.3 | E21: =$B$19*D21 -> 0.06 | F21: Ex: Leadership Goal | H21: 1.15 | I21: =IF(AND(H21>=O22,H21<=P22),1+((H21-1)/(P22-O22))*(T22-S22),IF(AND(H21>=N22,H21<O22),1-((1-H21)/(O22-N22))*(S22-R22),IF(H21>P22,T22,0))) -> 1.1 | K21: =I20*D20 -> 0.3 | M21: Objective 2 | N21: 0.9 | O21: 1 | P21: 1.1 | Q21: 0 | R21: 0.5 | S21: 1 | T21: 1.1
E22: =SUM(E15:E21) -> 1 | K22: =I21*D21 -> 0.33 | M22: Objective 3 | N22: 0.9 | O22: 1 | P22: 1.1 | Q22: 0 | R22: 0.5 | S22: 1 | T22: 1.1
F23: TOTAL PAYOUT (% of Target) | I23: =(I15*D15+I16*D16)*B15+(I19*D19+I20*D20+I21*D21)*B19 -> 1.2497084 | N23: Note: Performance between threshold and target, or target and max payout, will be interpolated.
G24: FY Bonus ($) | I24: =I23*C10 -> 218698.98 | K24: =SUM(K20:K22) -> 1.05
G25: Prorated Target | H25: Prorated Bonus | I25: =I23*C11 -> 0
J27: Financial | K27: =K17 -> 1.2996356 | N27: Attainment Levels and Payout Scale by Performance Measure
J28: Weight | K28: =B15 -> 0.8
B29: Target Total Direct Comp | P29: Attainment (% of Goal) | S29: Bonus Award (as % of Target Bonus)
B30: Base | C30: 350000 | N30: Weight | O30: Financial Measures | P30: Threshold | Q30: Target | R30: Max | S30: Threshold | T30: Target | U30: Max
B31: Target % | C31: 0.5 | N31: 0.8 | O31: Revenue | P31: 0.85 | Q31: 1 | R31: 1.15 | S31: 0.5 | T31: 1 | U31: 1.5
B32: Target $ | C32: =C31*C30 -> 175000 | O32: EBITDA | P32: 0.9 | Q32: 1 | R32: 1.1 | S32: 0.5 | T32: 1 | U32: 1.5
B33: Target Cash | C33: =C30+C32 -> 525000
B34: Annual LTI | C34: 200000 | N34: Weight | O34: Strategic Measures | P34: Threshold | Q34: Target | R34: Max | S34: Threshold | T34: Target | U34: Max
B35: Target Direct | C35: =C33+C34 -> 725000 | N35: 0.2 | O35: Objective 1 | P35: 0.9 | Q35: 1 | R35: 1.1 | S35: 0.5 | T35: 1 | U35: 1.1
O36: Objective 2 | P36: 0.9 | Q36: 1 | R36: 1.1 | S36: 0.5 | T36: 1 | U36: 1.1
O37: Objective 3 | P37: 0.9 | Q37: 1 | R37: 1.1 | S37: 0.5 | T37: 1 | U37: 1.1
N38: Figure X: Summary of attainment and payout levels for each AIP measure. Interpolation applies between thresholds.

Sheet Proration 
A2: Base | B2: 350000
A3: Target % | B3: 0.5
A4: Target $ | B4: =B3*B2 -> 175000
A5: Target / Actual $ | B5: =B2*B3 -> 175000 | E5: 46023
A6: Target Total Cash | B6: =B4+B2 -> 525000
C9: AIP Total Pro-rata %
C10: Jan | D10: Feb | E10: March | F10: April | G10: May | H10: June | I10: July | J10: Aug | K10: Sep | L10: Oct | M10: Nov | N10: Dec
C11: =($E$5-C$12)/365 -> 1 | D11: =($E$5-D$12)/365 -> 0.91506849 | E11: =($E$5-E$12)/365 -> 0.83835616 | F11: =($E$5-F$12)/365 -> 0.75342466 | G11: =($E$5-G$12)/365 -> 0.67123288 | H11: =($E$5-H$12)/365 -> 0.58630137 | I11: =($E$5-I$12)/365 -> 0.50410959 | J11: =($E$5-J$12)/365 -> 0.41917808 | ... N11: =($E$5-N$12)/365 -> 0.084931507
C12: 45658 | D12: 45689 | E12: 45717 | F12: 45748 | G12: 45778 | H12: 45809 | I12: 45839 | J12: 45870 | K12: 45901 | L12: 45931 | M12: 45962 | N12: 45992 | R12: =B6+B7 -> 525000
B13: AIP Target Payout | C13: =C$11*$B$4 -> 175000 | D13: =D$11*$B$4 -> 160136.99 | E13: =E$11*$B$4 -> 146712.33 | F13: =F$11*$B$4 -> 131849.32 | G13: =G$11*$B$4 -> 117465.75 | H13: =H$11*$B$4 -> 102602.74 | I13: =I$11*$B$4 -> 88219.178 | J13: =J$11*$B$4 -> 73356.164 | ... N13: =N$11*$B$4 -> 14863.014
B14: Max (150%) | C14: =C$13*150% -> 262500 | D14: =D$13*150% -> 240205.48 | E14: =E$13*150% -> 220068.49 | F14: =F$13*150% -> 197773.97 | G14: =G$13*150% -> 176198.63 | H14: =H$13*150% -> 153904.11 | I14: =I$13*150% -> 132328.77 | J14: =J$13*150% -> 110034.25 | ... N14: =N$13*150% -> 22294.521
C15: Hires on or after October 1 are not eligible for a payout unless an exception is approved by the Compensation Committee.

Sheet LTI Model- draft
B2: Job Level X Compensation | E2: Variables to be set by Compensation Committee: | I2: Job Level X | J2: Jobe Level Y | Q2: TABLE NOT APPLIED
B3: Base | C3: 350000 | E3: 1. Percent of EBITDA Growth delivered to Job Level X (and Leadership) | I3: 0.08 | J3: 0.05 | Q3: Attainment (% of Goal) | T3: Payout (as % of Target Bonus)
B4: Target % | C4: 0.5 | E4: 2. Maximum multiple of intended LTI value | I4: 5 | Q4: Threshold | R4: Target | S4: Max | T4: < Threshold | U4: Threshold | V4: Target | W4: Max
B5: Target $ | C5: 175000 | Q5: 0.5 | R5: 1 | S5: 1.1 | T5: 0 | U5: 0.75 | V5: 1 | W5: =I4 -> 5
B6: Target Cash | C6: =C3+C5 -> 525000
B7: Annual LTI | C7: 200000 | P7: Random | Q7: 1 = set random growth % by year | U7: X | V7: Y
B8: Target Direct | C8: =C6+C7 -> 725000 | P8: 1 | Q8: 2 = @Randbetween (X,Y) | U8: -5 | V8: 15 | W8: percent
E9: LTIP MODEL ($M) - Job Level X receives X% of EBITDA Growth over 3 year period | Q9: 3 = Monte Carlo Simulation
H10: Job Level X | J10: Leadership
D11: Scenario | H11: =I3 -> 0.08 | J11: =J3 -> 0.05
B12: =IF('LTI Model- draft'!$D$12="A",'Income Statement'!C30,IF('LTI Model- draft'!$D$12="B",'Income Statement'!C31,IF('LTI Model- draft'!$D$12="C",'Income Statement'!C32,IF('LTI Model- draft'!$D$12="D",'Income Statement'!C33,IF('LTI Model- draft'!$D$12="E",'Income Statement'!C34,IF('LTI Model- draft'!$D$12="F",'Income Statement'!C35,"error")))))) -> Custom - 10% growth per year | D12: E | F12: EBITDA ($M) | G12: Annual NI Growth ($M) | H12: Job Level X Tracking LTI Value | I12: Job Level X 3Yr Value | J12: Leadership Tracking LTI Value | K12: Leadership 3Yr Value | L12: Post LTI EBITDA ($M) | M12: Post LTI EBITDA Growth (%) | N12: Distribution
E13: 2024 | F13: 12.2658
D14: EBITDA Growth | E14: 2025 | F14: ='Income Statement'!$G$13/1000000 -> 13.010212
D15: =F15/F14-1 -> 0.06 | E15: 2026 | F15: ='Income Statement'!$H$13/1000000 -> 13.790824 | G15: =F15-F14 -> 0.7806127 | H15: =G15*I$3*1000000 -> 62449.016 | J15: =$G15*J$3*1000000 -> 39030.635 | L15: =F15-J15/1000000-H15/1000000 -> 13.689345 | M15: =L15/F14-1 -> 0.0522
D16: =F16/F15-1 -> 0.06 | E16: 2027 | F16: ='Income Statement'!$I$13/1000000 -> 14.618274 | G16: =F16-F15 -> 0.82744946 | H16: =G16*I$3*1000000 -> 66195.957 | J16: =$G16*J$3*1000000 -> 41372.473 | L16: =F16-J16/1000000-H16/1000000 -> 14.510705 | M16: =L16/F15-1 -> 0.0522
D17: =F17/F16-1 -> 0.06 | E17: 2028 | F17: ='Income Statement'!$J$13/1000000 -> 15.49537 | G17: =F17-F16 -> 0.87709643 | H17: =G17*I$3*1000000 -> 70167.714 | J17: =$G17*J$3*1000000 -> 43854.822 | L17: =F17-J17/1000000-H17/1000000 -> 15.381348 | M17: =L17/F16-1 -> 0.0522
D18: =F18/F17-1 -> 0.06 | E18: 2029 | F18: ='Income Statement'!$K$13/1000000 -> 16.425092 | G18: =F18-F17 -> 0.92972222 | H18: =G18*I$3*1000000 -> 74377.777 | I18: =IF(SUM(H15:H17)<0,0,IF(SUM(H15:H17)>$C$27*$I$4,$C$27*$I$4,SUM(H15:H17))) -> 198812.69 | J18: =$G18*J$3*1000000 -> 46486.111 | K18: =IF(SUM(J15:J17)<0,0,IF(SUM(J15:J17)>$C$27*$I$4,$C$27*$I$4,SUM(J15:J17))) -> 124257.93 | L18: =F18-J18/1000000-H18/1000000 -> 16.304229 | M18: =L18/F17-1 -> 0.0522
D19: =F19/F18-1 -> 0.06 | E19: 2030 | F19: ='Income Statement'!$L$13/1000000 -> 17.410598 | G19: =F19-F18 -> 0.98550555 | H19: =G19*I$3*1000000 -> 78840.444 | I19: =IF(SUM(H16:H18)<0,0,IF(SUM(H16:H18)>$C$27*$I$4,$C$27*$I$4,SUM(H16:H18))) -> 210741.45 | J19: =$G19*J$3*1000000 -> 49275.277 | K19: =IF(SUM(J16:J18)<0,0,IF(SUM(J16:J18)>$C$27*$I$4,$C$27*$I$4,SUM(J16:J18))) -> 131713.41 | L19: =F19-J19/1000000-H19/1000000 -> 17.282482 | M19: =L19/F18-1 -> 0.0522
D20: =F20/F19-1 -> 0.06 | E20: 2031 | F20: ='Income Statement'!$M$13/1000000 -> 18.455234 | G20: =F20-F19 -> 1.0446359 | H20: =G20*I$3*1000000 -> 83570.871 | I20: =IF(SUM(H17:H19)<0,0,IF(SUM(H17:H19)>$C$27*$I$4,$C$27*$I$4,SUM(H17:H19))) -> 223385.94 | J20: =$G20*J$3*1000000 -> 52231.794 | K20: =IF(SUM(J17:J19)<0,0,IF(SUM(J17:J19)>$C$27*$I$4,$C$27*$I$4,SUM(J17:J19))) -> 139616.21 | L20: =F20-J20/1000000-H20/1000000 -> 18.319431 | M20: =L20/F19-1 -> 0.0522
D21: =F21/F20-1 -> 0.06 | E21: 2032 | F21: ='Income Statement'!$N$13/1000000 -> 19.562548 | G21: =F21-F20 -> 1.107314 | H21: =G21*I$3*1000000 -> 88585.123 | I21: =IF(SUM(H18:H20)<0,0,IF(SUM(H18:H20)>$C$27*$I$4,$C$27*$I$4,SUM(H18:H20))) -> 236789.09 | J21: =$G21*J$3*1000000 -> 55365.702 | K21: =IF(SUM(J18:J20)<0,0,IF(SUM(J18:J20)>$C$27*$I$4,$C$27*$I$4,SUM(J18:J20))) -> 147993.18 | L21: =F21-J21/1000000-H21/1000000 -> 19.418597 | M21: =L21/F20-1 -> 0.0522
D22: =F22/F21-1 -> 0.06 | E22: 2033 | F22: ='Income Statement'!$O$13/1000000 -> 20.736301 | G22: =F22-F21 -> 1.1737529 | H22: =G22*I$3*1000000 -> 93900.23 | I22: =IF(SUM(H19:H21)<0,0,IF(SUM(H19:H21)>$C$27*$I$4,$C$27*$I$4,SUM(H19:H21))) -> 250996.44 | J22: =$G22*J$3*1000000 -> 58687.644 | K22: =IF(SUM(J19:J21)<0,0,IF(SUM(J19:J21)>$C$27*$I$4,$C$27*$I$4,SUM(J19:J21))) -> 156872.77 | L22: =F22-J22/1000000-H22/1000000 -> 20.583713 | M22: =L22/F21-1 -> 0.0522
B24: GRANT SCHEDULE
E25: Tracked Value | F25: =F27/($C$27/3) -> 0.93673524 | G25: =G27/($C$27/3) -> 0.99293936 | H25: =H27/($C$27/3) -> 1.0525157 | I25: =I28/($C$27/3) -> 1.1156667 | J25: =J29/($C$27/3) -> 1.1826067 | K25: =K30/($C$27/3) -> 1.2535631 | L25: =L31/($C$27/3) -> 1.3287768
B26: Award Date | C26: Award Target Value | F26: 2026 | G26: 2027 | H26: 2028 | I26: 2029 | J26: 2030 | K26: 2031 | L26: 2032 | M26: 2033
B27: Jan 2026 | C27: 200000 | E27: =1/3 -> 0.33333333 | F27: =H15 -> 62449.016 | G27: =H16 -> 66195.957 | H27: =H17 -> 70167.714 | I27: =I18 -> 198812.69
B28: Jan 2027 | C28: 200000 | E28: =1/3 -> 0.33333333 | G28: =G27 -> 66195.957 | H28: =H27 -> 70167.714 | I28: =H18 -> 74377.777 | J28: =I19 -> 210741.45
B29: Jan 2028 | C29: 250000 | E29: =1/3 -> 0.33333333 | H29: =H28 -> 70167.714 | I29: =I28 -> 74377.777 | J29: =H19 -> 78840.444 | K29: =I20 -> 223385.94
B30: Jan 2029 | C30: 200000 | E30: =1/3 -> 0.33333333 | I30: =I29 -> 74377.777 | J30: =J29 -> 78840.444 | K30: =H20 -> 83570.871 | L30: =I21 -> 236789.09
B31: Jan 2030 | C31: 200000 | E31: =1/3 -> 0.33333333 | J31: =J30 -> 78840.444 | K31: =K30 -> 83570.871 | L31: =H21 -> 88585.123 | M31: =I22 -> 250996.44
E32: Payout Value | I32: =I27 -> 198812.69 | J32: =J28 -> 210741.45 | K32: =K29 -> 223385.94 | L32: =L30 -> 236789.09 | M32: =M31 -> 250996.44
C35: Target Comp | E35: ESTIMATED REALIZED COMPENSATION
G36: 0.03 | H36: 0.03 | I36: 0.03 | J36: 0.03 | K36: 0.03 | L36: 0.03 | M36: 0.03
B37: Chief Executive Officer | E37: 2025 | F37: 2026 | G37: 2027 | H37: 2028 | I37: 2029 | J37: 2030 | K37: 2031 | L37: 2032 | M37: 2033
B38: Base | C38: 350000 | E38: =C38*50% -> 175000 | F38: =$C$38*1 -> 350000 | G38: =F38*(1+G36) -> 360500 | H38: =G38*(1+H36) -> 371315 | I38: =H38*(1+I36) -> 382454.45 | J38: =I38*(1+J36) -> 393928.08 | K38: =J38*(1+K36) -> 405745.93 | L38: =K38*(1+L36) -> 417918.3 | M38: =L38*(1+M36) -> 430455.85
B39: Target % | C39: 0.5
B40: Actual Payout % | F40: 1 | G40: 1 | H40: 1 | I40: 1.05 | J40: 1 | K40: 1 | L40: 1 | M40: 1 | P40: A | Q40: Aggressive (+X% over Linear Regression) | T40: 0.25
B41: Target / Actual $ | C41: =C38*C39 -> 175000 | E41: =C41*50% -> 87500 | F41: =$C$41*F40 -> 175000 | G41: =$C$41*G40 -> 175000 | H41: =$C$41*H40 -> 175000 | I41: =$C$41*I40 -> 183750 | J41: =$C$41*J40 -> 175000 | K41: =$C$41*K40 -> 175000 | L41: =$C$41*L40 -> 175000 | M41: =$C$41*M40 -> 175000 | P41: B | Q41: Linear Regression
B42: Target Cash | C42: =C38*(1+C39) -> 525000 | P42: C | Q42: Base Forecast
B43: Annual LTIP | C43: 225000 | I43: =I32 -> 198812.69 | J43: =J32 -> 210741.45 | K43: =K32 -> 223385.94 | L43: =L32 -> 236789.09 | M43: =M32 -> 250996.44 | P43: D | Q43: Conservative (-25%)
C44: =C42+C43 -> 750000 | E44: =E38+E41+E43 -> 262500 | F44: =F38+F41+F43 -> 525000 | G44: =G38+G41+G43 -> 535500 | H44: =H38+H41+H43 -> 546315 | I44: =I38+I41+I43 -> 765017.14 | J44: =J38+J41+J43 -> 779669.53 | K44: =K38+K41+K43 -> 804131.86 | L44: =L38+L41+L43 -> 829707.4 | M44: =M38+M41+M43 -> 856452.29 | P44: E | Q44: Custom - X% growth per year | T44: 0.06
...

Sheet Board Presentation Ideas- Draft
A2: Example CEO Fake Market Data and Internal Modeling Example (For Illustration Purposes)

Sheet Income Statement
C1: Sample Company
C2: Summarized Income Statement
C3: 2022 - 2024
D4: 0 | E4: 1 | F4: 2 | G4: 3 | H4: 4 | I4: 5 | J4: 6 | K4: 7 | L4: 8 | M4: 9 | N4: 10 | O4: 11
C5: Description | D5: 2022 | E5: 2023 | F5: 2024 | G5: 2025 | H5: 2026 | I5: 2027 | J5: 2028 | K5: 2029 | L5: 2030 | M5: 2031 | N5: 2032 | O5: 2033
C6: Total Sales | D6: 50265317 | E6: 62402646 | F6: 61988811 | G6: =IF('LTI Model- draft'!$D$12="A",G17,IF('LTI Model- draft'!$D$12="B",G18,IF('LTI Model- draft'!$D$12="C",G19,IF('LTI Model- draft'!$D$12="D",G20,IF('LTI Model- draft'!$D$12="E",G21,IF('LTI Model- draft'!$D$12="F",G22,"error")))))) -> 65708140 | H6: =IF('LTI Model- draft'!$D$12="A",H17,IF('LTI Model- draft'!$D$12="B",H18,IF('LTI Model- draft'!$D$12="C",H19,IF('LTI Model- draft'!$D$12="D",H20,IF('LTI Model- draft'!$D$12="E",H21,IF('LTI Model- draft'!$D$12="F",H22,"error")))))) -> 69650628 | I6: =IF('LTI Model- draft'!$D$12="A",I17,IF('LTI Model- draft'!$D$12="B",I18,IF('LTI Model- draft'!$D$12="C",I19,IF('LTI Model- draft'!$D$12="D",I20,IF('LTI Model- draft'!$D$12="E",I21,IF('LTI Model- draft'!$D$12="F",I22,"error")))))) -> 73829666 | J6: =IF('LTI Model- draft'!$D$12="A",J17,IF('LTI Model- draft'!$D$12="B",J18,IF('LTI Model- draft'!$D$12="C",J19,IF('LTI Model- draft'!$D$12="D",J20,IF('LTI Model- draft'!$D$12="E",J21,IF('LTI Model- draft'!$D$12="F",J22,"error")))))) -> 78259446 | K6: =IF('LTI Model- draft'!$D$12="A",K17,IF('LTI Model- draft'!$D$12="B",K18,IF('LTI Model- draft'!$D$12="C",K19,IF('LTI Model- draft'!$D$12="D",K20,IF('LTI Model- draft'!$D$12="E",K21,IF('LTI Model- draft'!$D$12="F",K22,"error")))))) -> 82955013 | L6: =IF('LTI Model- draft'!$D$12="A",L17,IF('LTI Model- draft'!$D$12="B",L18,IF('LTI Model- draft'!$D$12="C",L19,IF('LTI Model- draft'!$D$12="D",L20,IF('LTI Model- draft'!$D$12="E",L21,IF('LTI Model- draft'!$D$12="F",L22,"error")))))) -> 87932313 | M6: =IF('LTI Model- draft'!$D$12="A",M17,IF('LTI Model- draft'!$D$12="B",M18,IF('LTI Model- draft'!$D$12="C",M19,IF('LTI Model- draft'!$D$12="D",M20,IF('LTI Model- draft'!$D$12="E",M21,IF('LTI Model- draft'!$D$12="F",M22,"error")))))) -> 93208252 | N6: =IF('LTI Model- draft'!$D$12="A",N17,IF('LTI Model- draft'!$D$12="B",N18,IF('LTI Model- draft'!$D$12="C",N19,IF('LTI Model- draft'!$D$12="D",N20,IF('LTI Model- draft'!$D$12="E",N21,IF('LTI Model- draft'!$D$12="F",N22,"error")))))) -> 98800747 | O6: =IF('LTI Model- draft'!$D$12="A",O17,IF('LTI Model- draft'!$D$12="B",O18,IF('LTI Model- draft'!$D$12="C",O19,IF('LTI Model- draft'!$D$12="D",O20,IF('LTI Model- draft'!$D$12="E",O21,IF('LTI Model- draft'!$D$12="F",O22,"error")))))) -> 1.0472879e+08
C7: Total COGS | D7: =31121821.545+2383563 -> 33505385 | E7: =34796929.7317+4017325 -> 38814255 | F7: =33800971.4496+3591107 -> 37392078
C8: Total Product Margin | D8: =+D6-D7 -> 16759932 | E8: =+E6-E7 -> 23588391 | F8: =+F6-F7 -> 24596733
C9: Total SG&A | D9: 9132437.7 | E9: 10150353 | F9: 12389730
C10: Total Manufacturing Income | D10: =+D8-D9 -> 7627494.4 | E10: =+E8-E9 -> 13438038 | F10: =+F8-F9 -> 12207003
C11: Total Farm Net Income/(Loss) | D11: -2853651.3 | E11: -2309284.4 | F11: -1819550.7
C12: Total Other Income/(Expense) | D12: -1455787.9 | E12: 1033799.6 | F12: 1878347.1
C13: EBITDA | D13: =+D10+D11+D12 -> 3318055.2 | E13: =+E10+E11+E12 -> 12162553 | F13: =+F10+F11+F12 -> 12265800 | G13: =G6*G14 -> 13010212 | H13: =H6*H14 -> 13790824 | I13: =I6*I14 -> 14618274 | J13: =J6*J14 -> 15495370 | K13: =K6*K14 -> 16425092 | L13: =L6*L14 -> 17410598 | M13: =M6*M14 -> 18455234 | N13: =N6*N14 -> 19562548 | O13: =O6*O14 -> 20736301
F14: =F13/F6 -> 0.19787119 | G14: =19.8% -> 0.198 | H14: =19.8% -> 0.198 | I14: =19.8% -> 0.198 | J14: =19.8% -> 0.198 | K14: =19.8% -> 0.198 | L14: =19.8% -> 0.198 | M14: =19.8% -> 0.198 | N14: =19.8% -> 0.198 | O14: =19.8% -> 0.198
C17: Aggressive (+X% over Regression) | D17: =D18 -> 50265317 | E17: =E18 -> 62402646 | F17: =F18 -> 61988811 | G17: =F17*(1+G24) -> 71936172 | H17: =G17*(1+H24) -> 79471700 | I17: =H17*(1+I24) -> 87152895 | J17: =I17*(1+J24) -> 94971915 | K17: =J17*(1+K24) -> 1.0328196e+08 | L17: =K17*(1+L24) -> 1.1244823e+08 | M17: =L17*(1+M24) -> 1.2270913e+08 | N17: =M17*(1+N24) -> 1.3421311e+08 | O17: =N17*(1+O24) -> 1.4729889e+08
C18: Linear Regression | D18: =D$6 -> 50265317 | E18: =E$6 -> 62402646 | F18: =F$6 -> 61988811 | G18: =F18*(1+G25) -> 69946700 | H18: =G18*(1+H25) -> 75808400 | I18: =H18*(1+I25) -> 81670100 | J18: =I18*(1+J25) -> 87531800 | K18: =J18*(1+K25) -> 93659026 | L18: =K18*(1+L25) -> 1.0030882e+08 | M18: =L18*(1+M25) -> 1.0763136e+08 | N18: =M18*(1+N25) -> 1.1570371e+08 | O18: =N18*(1+O25) -> 1.247286e+08
C19: Base Forecast | D19: =D$6 -> 50265317 | E19: =E$6 -> 62402646 | F19: =F$6 -> 61988811 | G19: =F19*(1+G26) -> 68000000 | H19: =G19*(1+H26) -> 72273921 | I19: =H19*(1+I26) -> 76465225 | J19: =I19*(1+J26) -> 80581323 | K19: =J19*(1+K26) -> 84811843 | L19: =K19*(1+L26) -> 89328074 | M19: =L19*(1+M26) -> 94218786 | N19: =M19*(1+N26) -> 99518592 | O19: =N19*(1+O26) -> 1.0534043e+08
C20: Conservative (-25%) | D20: =D18 -> 50265317 | E20: =E18 -> 62402646 | F20: =F18 -> 61988811 | G20: =F20*(1+G27) -> 66497203 | H20: =G20*(1+H27) -> 69631804 | I20: =H20*(1+I27) -> 72660365 | J20: =I20*(1+J27) -> 75593828 | K20: =J20*(1+K27) -> 78570335 | L20: =K20*(1+L27) -> 81708238 | M20: =L20*(1+M27) -> 85063383 | N20: =M20*(1+N27) -> 88651994 | O20: =N20*(1+O27) -> 92541600
C21: Custom - 10% growth per year | D21: =D$6 -> 50265317 | E21: =E$6 -> 62402646 | F21: =F$6 -> 61988811 | G21: =G34*1000000 -> 65708140 | H21: =H34*1000000 -> 69650628 | I21: =I34*1000000 -> 73829666 | J21: =J34*1000000 -> 78259446 | K21: =K34*1000000 -> 82955013 | L21: =L34*1000000 -> 87932313 | M21: =M34*1000000 -> 93208252 | N21: =N34*1000000 -> 98800747 | O21: =O34*1000000 -> 1.0472879e+08
C22: Custom - Random Growth | D22: =D$6 -> 50265317 | E22: =E$6 -> 62402646 | F22: =F$6 -> 61988811 | G22: =G35*1000000 -> 65088252 | H22: =H35*1000000 -> 62484722 | I22: =I35*1000000 -> 69982888 | J22: =J35*1000000 -> 70682717 | K22: =K35*1000000 -> 81285125 | L22: =L35*1000000 -> 80472273 | M22: =M35*1000000 -> 89324224 | N22: =N35*1000000 -> 84858012 | O22: =O35*1000000 -> 86555173
B24: 1 | E24: Growth Rates | F24: Aggressive | G24: =G25*(1+'LTI Model- draft'!$T$40) -> 0.16047027 | H24: =H25*(1+'LTI Model- draft'!$T$40) -> 0.10475298 | I24: =I25*(1+'LTI Model- draft'!$T$40) -> 0.096653207 | J24: =J25*(1+'LTI Model- draft'!$T$40) -> 0.089716126 | K24: =K25*(1+'LTI Model- draft'!$T$40) -> 0.0875 | L24: =L25*(1+'LTI Model- draft'!$T$40) -> 0.08875 | M24: =M25*(1+'LTI Model- draft'!$T$40) -> 0.09125 | N24: =N25*(1+'LTI Model- draft'!$T$40) -> 0.09375 | O24: =O25*(1+'LTI Model- draft'!$T$40) -> 0.0975
B25: 2 | D25: Fixed | F25: Linear Regression | G25: 0.12837621 | H25: 0.083802381 | I25: 0.077322566 | J25: 0.071772901 | K25: 0.07 | L25: 0.071 | M25: 0.073 | N25: 0.075 | O25: 0.078
B26: 3 | C26: Solve for growth % that = $68M | D26: 1.0071664 | E26: 0.75 | F26: Base Forecast | G26: =G25*75%*D26 -> 0.096972159 | H26: =H25*$E$26 -> 0.062851786 | I26: =I25*$E$26 -> 0.057991924 | J26: =J25*$E$26 -> 0.053829676 | K26: =K25*$E$26 -> 0.0525 | L26: =L25*$E$26 -> 0.05325 | M26: =M25*$E$26 -> 0.05475 | N26: =N25*$E$26 -> 0.05625 | O26: =O25*$E$26 -> 0.0585
B27: 4 | D27: -0.25 | F27: Conservative | G27: =G26*(1+$D$27) -> 0.072729119 | H27: =H26*0.75 -> 0.047138839 | I27: =I26*0.75 -> 0.043493943 | J27: =J26*0.75 -> 0.040372257 | K27: =K26*0.75 -> 0.039375 | L27: =L26*0.75 -> 0.0399375 | M27: =M26*0.75 -> 0.0410625 | N27: =N26*0.75 -> 0.0421875 | O27: =O26*0.75 -> 0.043875
D29: 2022 | E29: 2023 | F29: 2024 | G29: 2025 | H29: 2026 | I29: 2027 | J29: 2028 | K29: 2029 | L29: 2030 | M29: 2031 | N29: 2032 | O29: 2033
A30: A | C30: Aggressive (+X% over Regression) | D30: =D17/1000000 -> 50.265317 | E30: =E17/1000000 -> 62.402646 | F30: =F17/1000000 -> 61.988811 | G30: =G17/1000000 -> 71.936172 | H30: =H17/1000000 -> 79.4717 | I30: =I17/1000000 -> 87.152895 | J30: =J17/1000000 -> 94.971915 | K30: =K17/1000000 -> 103.28196 | ... O30: =O17/1000000 -> 147.29889
A31: B | C31: Linear Regression | D31: =D18/1000000 -> 50.265317 | E31: =E18/1000000 -> 62.402646 | F31: =F18/1000000 -> 61.988811 | G31: =G18/1000000 -> 69.9467 | H31: =H18/1000000 -> 75.8084 | I31: =I18/1000000 -> 81.6701 | J31: =J18/1000000 -> 87.5318 | K31: =K18/1000000 -> 93.659026 | ... O31: =O18/1000000 -> 124.7286
A32: C | C32: Base Forecast | D32: =D19/1000000 -> 50.265317 | E32: =E19/1000000 -> 62.402646 | F32: =F19/1000000 -> 61.988811 | G32: =G19/1000000 -> 68 | H32: =H19/1000000 -> 72.273921 | I32: =I19/1000000 -> 76.465225 | J32: =J19/1000000 -> 80.581323 | K32: =K19/1000000 -> 84.811843 | ... O32: =O19/1000000 -> 105.34043
A33: D | C33: Conservative (-25%) | D33: =D20/1000000 -> 50.265317 | E33: =E20/1000000 -> 62.402646 | F33: =F20/1000000 -> 61.988811 | G33: =G20/1000000 -> 66.497203 | H33: =H20/1000000 -> 69.631804 | I33: =I20/1000000 -> 72.660365 | J33: =J20/1000000 -> 75.593828 | K33: =K20/1000000 -> 78.570335 | ... O33: =O20/1000000 -> 92.5416
A34: E | C34: Custom - 10% growth per year | D34: =D33 -> 50.265317 | E34: =E33 -> 62.402646 | F34: =F33 -> 61.988811 | G34: =F34*(1+'LTI Model- draft'!$T$44) -> 65.70814 | H34: =G34*(1+'LTI Model- draft'!$T$44) -> 69.650628 | I34: =H34*(1+'LTI Model- draft'!$T$44) -> 73.829666 | J34: =I34*(1+'LTI Model- draft'!$T$44) -> 78.259446 | K34: =J34*(1+'LTI Model- draft'!$T$44) -> 82.955013 | L34: =K34*(1+'LTI Model- draft'!$T$44) -> 87.932313 | M34: =L34*(1+'LTI Model- draft'!$T$44) -> 93.208252 | N34: =M34*(1+'LTI Model- draft'!$T$44) -> 98.800747 | O34: =N34*(1+'LTI Model- draft'!$T$44) -> 104.72879
A35: F | C35: Custom - Random Growth | D35: =D34 -> 50.265317 | E35: =E34 -> 62.402646 | F35: =F34 -> 61.988811 | G35: =F35*(1+G36) -> 65.088252 | H35: =G35*(1+H36) -> 62.484722 | I35: =H35*(1+I36) -> 69.982888 | J35: =I35*(1+J36) -> 70.682717 | K35: =J35*(1+K36) -> 81.285125 | L35: =K35*(1+L36) -> 80.472273 | M35: =L35*(1+M36) -> 89.324224 | N35: =M35*(1+N36) -> 84.858012 | O35: =N35*(1+O36) -> 86.555173
F36: Random Growth: | G36: =IF('LTI Model- draft'!$P$8=1,'LTI Model- draft'!R48,IF('LTI Model- draft'!$P$8=2,'LTI Model- draft'!R49,'LTI Model- draft'!R50)) -> 0.05 | H36: =IF('LTI Model- draft'!$P$8=1,'LTI Model- draft'!S48,IF('LTI Model- draft'!$P$8=2,'LTI Model- draft'!S49,'LTI Model- draft'!S50)) -> -0.04 | I36: =IF('LTI Model- draft'!$P$8=1,'LTI Model- draft'!T48,IF('LTI Model- draft'!$P$8=2,'LTI Model- draft'!T49,'LTI Model- draft'!T50)) -> 0.12 | J36: =IF('LTI Model- draft'!$P$8=1,'LTI Model- draft'!U48,IF('LTI Model- draft'!$P$8=2,'LTI Model- draft'!U49,'LTI Model- draft'!U50)) -> 0.01 | K36: =IF('LTI Model- draft'!$P$8=1,'LTI Model- draft'!V48,IF('LTI Model- draft'!$P$8=2,'LTI Model- draft'!V49,'LTI Model- draft'!V50)) -> 0.15 | L36: =IF('LTI Model- draft'!$P$8=1,'LTI Model- draft'!W48,IF('LTI Model- draft'!$P$8=2,'LTI Model- draft'!W49,'LTI Model- draft'!W50)) -> -0.01 | M36: =IF('LTI Model- draft'!$P$8=1,'LTI Model- draft'!X48,IF('LTI Model- draft'!$P$8=2,'LTI Model- draft'!X49,'LTI Model- draft'!X50)) -> 0.11 | N36: =IF('LTI Model- draft'!$P$8=1,'LTI Model- draft'!Y48,IF('LTI Model- draft'!$P$8=2,'LTI Model- draft'!Y49,'LTI Model- draft'!Y50)) -> -0.05 | O36: =IF('LTI Model- draft'!$P$8=1,'LTI Model- draft'!Z48,IF('LTI Model- draft'!$P$8=2,'LTI Model- draft'!Z49,'LTI Model- draft'!Z50)) -> 0.02
E37: From LTI Page (Cell P8): | F37: ='LTI Model- draft'!P8 -> 1
C39: 0.11050992
B42: SIM | C42: Mean Growth | D42: =AVERAGE(E42:G42) -> 0.098277868 | E42: =E6/D6-1 -> 0.24146529 | F42: =F6/E6-1 -> -0.0066316847 | G42: =G6/F6-1 -> 0.06
D43: =_xlfn.STDEV.S(D6:G6)/C45 -> 0.11247465
C45: =AVERAGE(D6:G6) -> 60091228
D75: 2022 | E75: 2023 | F75: 2024 | G75: 2025 | H75: 2026 | I75: 2027 | J75: 2028 | K75: 2029 | L75: 2030 | M75: 2031 | N75: 2032 | O75: 2033
C76: Aggressive (+10%) | D76: =$D$13/1000000 -> 3.3180552 | E76: =$E$13/1000000 -> 12.162553 | F76: =$F$13/1000000 -> 12.2658 | G76: =(G17*19.8%)/1000000 -> 14.243362 | H76: =(H17*19.8%)/1000000 -> 15.735397 | I76: =(I17*19.8%)/1000000 -> 17.256273 | J76: =(J17*19.8%)/1000000 -> 18.804439 | K76: =(K17*19.8%)/1000000 -> 20.449828 | L76: =(L17*19.8%)/1000000 -> 22.26475 | M76: =(M17*19.8%)/1000000 -> 24.296408 | N76: =(N17*19.8%)/1000000 -> 26.574197 | O76: =(O17*19.8%)/1000000 -> 29.165181
C77: Linear Regression | D77: =$D$13/1000000 -> 3.3180552 | E77: =$E$13/1000000 -> 12.162553 | F77: =$F$13/1000000 -> 12.2658 | G77: =(G18*19.8%)/1000000 -> 13.849447 | H77: =(H18*19.8%)/1000000 -> 15.010063 | I77: =(I18*19.8%)/1000000 -> 16.17068 | J77: =(J18*19.8%)/1000000 -> 17.331296 | K77: =(K18*19.8%)/1000000 -> 18.544487 | L77: =(L18*19.8%)/1000000 -> 19.861146 | M77: =(M18*19.8%)/1000000 -> 21.311009 | N77: =(N18*19.8%)/1000000 -> 22.909335 | O77: =(O18*19.8%)/1000000 -> 24.696263
...

Sheet Simulations
C2: Parameter | D2: Value
C3: Initial Value | D3: 61.988811
C4: Mean Growth (µ) | D4: 0.1
C5: Std Dev (σ) | D5: 0.4
C6: Time Horizon | D6: 10 years
C7: # of Simulations | D7: 1000
C9: Metric | D9: Value
C10: Mean Final Value | D10: =AVERAGE(Simulations!F27:ALQ27) -> 169.26836
C11: Median Final Value | D11: =MEDIAN(Simulations!F27:ALQ27) -> 77.255793
C12: 10th Percentile | D12: =_xlfn.PERCENTILE.INC(Simulations!F27:ALQ27, 0.1) -> 7.7223061
C13: 90th Percentile | D13: =_xlfn.PERCENTILE.INC(Simulations!F27:ALQ27, 0.9) -> 403.48266
D16: Average | E16: Year | F16: Sim 1 | G16: Sim 2 | H16: Sim 3 | I16: Sim 4 | J16: Sim 5 | K16: Sim 6 | L16: Sim 7 | M16: Sim 8 | N16: Sim 9 | O16: Sim 10 | P16: Sim 11 | Q16: Sim 12 | R16: Sim 13 | S16: Sim 14 | T16: Sim 15 | U16: Sim 16 | V16: Sim 17 | W16: Sim 18 | X16: Sim 19 | Y16: Sim 20 | Z16: Sim 21 | AA16: Sim 22 | AB16: Sim 23 | AC16: Sim 24 | AD16: Sim 25 | AE16: Sim 26 | AF16: Sim 27 | AG16: Sim 28 | AH16: Sim 29 | AI16: Sim 30 | AJ16: Sim 31 | AK16: Sim 32 | AL16: Sim 33 | AM16: Sim 34 | AN16: Sim 35 | AO16: Sim 36 | AP16: Sim 37 | AQ16: Sim 38 | AR16: Sim 39 | AS16: Sim 40 | AT16: Sim 41 | AU16: Sim 42 | AV16: Sim 43 | AW16: Sim 44 | AX16: Sim 45 | AY16: Sim 46 | AZ16: Sim 47 | BA16: Sim 48 | BB16: Sim 49 | BC16: Sim 50 | BD16: Sim 51 | BE16: Sim 52 | BF16: Sim 53 | BG16: Sim 54 | BH16: Sim 55 | BI16: Sim 56 | BJ16: Sim 57 | BK16: Sim 58 | BL16: Sim 59 | BM16: Sim 60 | BN16: Sim 61 | BO16: Sim 62 | BP16: Sim 63 | BQ16: Sim 64 | BR16: Sim 65 | BS16: Sim 66 | BT16: Sim 67 | BU16: Sim 68 | BV16: Sim 69 | BW16: Sim 70 | BX16: Sim 71 | BY16: Sim 72 | BZ16: Sim 73 | CA16: Sim 74 | CB16: Sim 75 | CC16: Sim 76 | CD16: Sim 77 | CE16: Sim 78 | CF16: Sim 79 | CG16: Sim 80 | CH16: Sim 81 | CI16: Sim 82 | CJ16: Sim 83 | CK16: Sim 84 | CL16: Sim 85 | CM16: Sim 86 | CN16: Sim 87 | CO16: Sim 88 | CP16: Sim 89 | CQ16: Sim 90 | CR16: Sim 91 | CS16: Sim 92 | CT16: Sim 93 | CU16: Sim 94 | CV16: Sim 95 | CW16: Sim 96 | CX16: Sim 97 | CY16: Sim 98 | CZ16: Sim 99 | DA16: Sim 100 | DB16: Sim 101 | DC16: Sim 102 | DD16: Sim 103 | DE16: Sim 104 | DF16: Sim 105 | DG16: Sim 106 | DH16: Sim 107 | DI16: Sim 108 | DJ16: Sim 109 | DK16: Sim 110 | DL16: Sim 111 | DM16: Sim 112 | DN16: Sim 113 | DO16: Sim 114 | DP16: Sim 115 | DQ16: Sim 116 | DR16: Sim 117 | DS16: Sim 118 | DT16: Sim 119 | DU16: Sim 120 | DV16: Sim 121 | DW16: Sim 122 | DX16: Sim 123 | DY16: Sim 124 | DZ16: Sim 125 | EA16: Sim 126 | EB16: Sim 127 | EC16: Sim 128 | ED16: Sim 129 | EE16: Sim 130 | EF16: Sim 131 | EG16: Sim 132 | EH16: Sim 133 | EI16: Sim 134 | EJ16: Sim 135 | EK16: Sim 136 | EL16: Sim 137 | EM16: Sim 138 | EN16: Sim 139 | EO16: Sim 140 | EP16: Sim 141 | EQ16: Sim 142 | ER16: Sim 143 | ES16: Sim 144 | ET16: Sim 145 | EU16: Sim 146 | EV16: Sim 147 | EW16: Sim 148 | EX16: Sim 149 | EY16: Sim 150 | EZ16: Sim 151 | FA16: Sim 152 | FB16: Sim 153 | FC16: Sim 154 | FD16: Sim 155 | FE16: Sim 156 | FF16: Sim 157 | FG16: Sim 158 | FH16: Sim 159 | FI16: Sim 160 | FJ16: Sim 161 | FK16: Sim 162 | FL16: Sim 163 | FM16: Sim 164 | FN16: Sim 165 | FO16: Sim 166 | FP16: Sim 167 | FQ16: Sim 168 | FR16: Sim 169 | FS16: Sim 170 | FT16: Sim 171 | FU16: Sim 172 | FV16: Sim 173 | FW16: Sim 174 | FX16: Sim 175 | FY16: Sim 176 | FZ16: Sim 177 | GA16: Sim 178 | GB16: Sim 179 | GC16: Sim 180 | GD16: Sim 181 | GE16: Sim 182 | GF16: Sim 183 | GG16: Sim 184 | GH16: Sim 185 | GI16: Sim 186 | GJ16: Sim 187 | GK16: Sim 188 | GL16: Sim 189 | GM16: Sim 190 | GN16: Sim 191 | GO16: Sim 192 | GP16: Sim 193 | GQ16: Sim 194 | GR16: Sim 195 | GS16: Sim 196 | GT16: Sim 197 | GU16: Sim 198 | GV16: Sim 199 | GW16: Sim 200 | GX16: Sim 201 | GY16: Sim 202 | GZ16: Sim 203 | HA16: Sim 204 | HB16: Sim 205 | HC16: Sim 206 | HD16: Sim 207 | HE16: Sim 208 | HF16: Sim 209 | HG16: Sim 210 | HH16: Sim 211 | HI16: Sim 212 | HJ16: Sim 213 | HK16: Sim 214 | HL16: Sim 215 | HM16: Sim 216 | HN16: Sim 217 | HO16: Sim 218 | HP16: Sim 219 | HQ16: Sim 220 | HR16: Sim 221 | HS16: Sim 222 | HT16: Sim 223 | HU16: Sim 224 | HV16: Sim 225 | HW16: Sim 226 | HX16: Sim 227 | HY16: Sim 228 | HZ16: Sim 229 | IA16: Sim 230 | IB16: Sim 231 | IC16: Sim 232 | ID16: Sim 233 | IE16: Sim 234 | IF16: Sim 235 | IG16: Sim 236 | IH16: Sim 237 | II16: Sim 238 | IJ16: Sim 239 | IK16: Sim 240 | IL16: Sim 241 | IM16: Sim 242 | IN16: Sim 243 | IO16: Sim 244 | IP16: Sim 245 | IQ16: Sim 246 | IR16: Sim 247 | IS16: Sim 248 | IT16: Sim 249 | IU16: Sim 250 | IV16: Sim 251 | IW16: Sim 252 | IX16: Sim 253 | IY16: Sim 254 | IZ16: Sim 255 | JA16: Sim 256 | JB16: Sim 257 | JC16: Sim 258 | JD16: Sim 259 | JE16: Sim 260 | JF16: Sim 261 | JG16: Sim 262 | JH16: Sim 263 | JI16: Sim 264 | JJ16: Sim 265 | JK16: Sim 266 | JL16: Sim 267 | JM16: Sim 268 | JN16: Sim 269 | JO16: Sim 270 | JP16: Sim 271 | JQ16: Sim 272 | JR16: Sim 273 | JS16: Sim 274 | JT16: Sim 275 | JU16: Sim 276 | JV16: Sim 277 | JW16: Sim 278 | JX16: Sim 279 | JY16: Sim 280 | JZ16: Sim 281 | KA16: Sim 282 | KB16: Sim 283 | KC16: Sim 284 | KD16: Sim 285 | KE16: Sim 286 | KF16: Sim 287 | KG16: Sim 288 | KH16: Sim 289 | KI16: Sim 290 | KJ16: Sim 291 | KK16: Sim 292 | KL16: Sim 293 | KM16: Sim 294 | KN16: Sim 295 | KO16: Sim 296 | KP16: Sim 297 | KQ16: Sim 298 | KR16: Sim 299 | KS16: Sim 300 | KT16: Sim 301 | KU16: Sim 302 | KV16: Sim 303 | KW16: Sim 304 | KX16: Sim 305 | KY16: Sim 306 | KZ16: Sim 307 | LA16: Sim 308 | LB16: Sim 309 | LC16: Sim 310 | LD16: Sim 311 | LE16: Sim 312 | LF16: Sim 313 | LG16: Sim 314 | LH16: Sim 315 | LI16: Sim 316 | LJ16: Sim 317 | LK16: Sim 318 | LL16: Sim 319 | LM16: Sim 320 | LN16: Sim 321 | LO16: Sim 322 | LP16: Sim 323 | LQ16: Sim 324 | LR16: Sim 325 | LS16: Sim 326 | LT16: Sim 327 | LU16: Sim 328 | LV16: Sim 329 | LW16: Sim 330 | LX16: Sim 331 | LY16: Sim 332 | LZ16: Sim 333 | MA16: Sim 334 | MB16: Sim 335 | MC16: Sim 336 | MD16: Sim 337 | ME16: Sim 338 | MF16: Sim 339 | MG16: Sim 340 | MH16: Sim 341 | MI16: Sim 342 | MJ16: Sim 343 | MK16: Sim 344 | ML16: Sim 345 | MM16: Sim 346 | MN16: Sim 347 | MO16: Sim 348 | MP16: Sim 349 | MQ16: Sim 350 | MR16: Sim 351 | MS16: Sim 352 | MT16: Sim 353 | MU16: Sim 354 | MV16: Sim 355 | MW16: Sim 356 | MX16: Sim 357 | MY16: Sim 358 | MZ16: Sim 359 | NA16: Sim 360 | NB16: Sim 361 | NC16: Sim 362 | ND16: Sim 363 | NE16: Sim 364 | NF16: Sim 365 | NG16: Sim 366 | NH16: Sim 367 | NI16: Sim 368 | NJ16: Sim 369 | NK16: Sim 370 | NL16: Sim 371 | NM16: Sim 372 | NN16: Sim 373 | NO16: Sim 374 | NP16: Sim 375 | NQ16: Sim 376 | NR16: Sim 377 | NS16: Sim 378 | NT16: Sim 379 | NU16: Sim 380 | NV16: Sim 381 | NW16: Sim 382 | NX16: Sim 383 | NY16: Sim 384 | NZ16: Sim 385 | OA16: Sim 386 | OB16: Sim 387 | OC16: Sim 388 | OD16: Sim 389 | OE16: Sim 390 | OF16: Sim 391 | OG16: Sim 392 | OH16: Sim 393 | OI16: Sim 394 | OJ16: Sim 395 | OK16: Sim 396 | OL16: Sim 397 | OM16: Sim 398 | ON16: Sim 399 | OO16: Sim 400 | OP16: Sim 401 | OQ16: Sim 402 | OR16: Sim 403 | OS16: Sim 404 | OT16: Sim 405 | OU16: Sim 406 | OV16: Sim 407 | OW16: Sim 408 | OX16: Sim 409 | OY16: Sim 410 | OZ16: Sim 411 | PA16: Sim 412 | PB16: Sim 413 | PC16: Sim 414 | PD16: Sim 415 | PE16: Sim 416 | PF16: Sim 417 | PG16: Sim 418 | PH16: Sim 419 | PI16: Sim 420 | PJ16: Sim 421 | PK16: Sim 422 | PL16: Sim 423 | PM16: Sim 424 | PN16: Sim 425 | PO16: Sim 426 | PP16: Sim 427 | PQ16: Sim 428 | PR16: Sim 429 | PS16: Sim 430 | PT16: Sim 431 | PU16: Sim 432 | PV16: Sim 433 | PW16: Sim 434 | PX16: Sim 435 | PY16: Sim 436 | PZ16: Sim 437 | QA16: Sim 438 | QB16: Sim 439 | QC16: Sim 440 | QD16: Sim 441 | QE16: Sim 442 | QF16: Sim 443 | QG16: Sim 444 | QH16: Sim 445 | QI16: Sim 446 | QJ16: Sim 447 | QK16: Sim 448 | QL16: Sim 449 | QM16: Sim 450 | QN16: Sim 451 | QO16: Sim 452 | QP16: Sim 453 | QQ16: Sim 454 | QR16: Sim 455 | QS16: Sim 456 | QT16: Sim 457 | QU16: Sim 458 | QV16: Sim 459 | QW16: Sim 460 | QX16: Sim 461 | QY16: Sim 462 | QZ16: Sim 463 | RA16: Sim 464 | RB16: Sim 465 | RC16: Sim 466 | RD16: Sim 467 | RE16: Sim 468 | RF16: Sim 469 | RG16: Sim 470 | RH16: Sim 471 | RI16: Sim 472 | RJ16: Sim 473 | RK16: Sim 474 | RL16: Sim 475 | RM16: Sim 476 | RN16: Sim 477 | RO16: Sim 478 | RP16: Sim 479 | RQ16: Sim 480 | RR16: Sim 481 | RS16: Sim 482 | RT16: Sim 483 | RU16: Sim 484 | RV16: Sim 485 | RW16: Sim 486 | RX16: Sim 487 | RY16: Sim 488 | RZ16: Sim 489 | SA16: Sim 490 | SB16: Sim 491 | SC16: Sim 492 | SD16: Sim 493 | SE16: Sim 494 | SF16: Sim 495 | SG16: Sim 496 | SH16: Sim 497 | SI16: Sim 498 | SJ16: Sim 499 | SK16: Sim 500 | SL16: Sim 501 | SM16: Sim 502 | SN16: Sim 503 | SO16: Sim 504 | SP16: Sim 505 | SQ16: Sim 506 | SR16: Sim 507 | SS16: Sim 508 | ST16: Sim 509 | SU16: Sim 510 | SV16: Sim 511 | SW16: Sim 512 | SX16: Sim 513 | SY16: Sim 514 | SZ16: Sim 515 | TA16: Sim 516 | TB16: Sim 517 | TC16: Sim 518 | TD16: Sim 519 | TE16: Sim 520 | TF16: Sim 521 | TG16: Sim 522 | TH16: Sim 523 | TI16: Sim 524 | TJ16: Sim 525 | TK16: Sim 526 | TL16: Sim 527 | TM16: Sim 528 | TN16: Sim 529 | TO16: Sim 530 | TP16: Sim 531 | TQ16: Sim 532 | TR16: Sim 533 | TS16: Sim 534 | TT16: Sim 535 | TU16: Sim 536 | TV16: Sim 537 | TW16: Sim 538 | TX16: Sim 539 | TY16: Sim 540 | TZ16: Sim 541 | UA16: Sim 542 | UB16: Sim 543 | UC16: Sim 544 | UD16: Sim 545 | UE16: Sim 546 | UF16: Sim 547 | UG16: Sim 548 | UH16: Sim 549 | UI16: Sim 550 | UJ16: Sim 551 | UK16: Sim 552 | UL16: Sim 553 | UM16: Sim 554 | UN16: Sim 555 | UO16: Sim 556 | UP16: Sim 557 | UQ16: Sim 558 | UR16: Sim 559 | US16: Sim 560 | UT16: Sim 561 | UU16: Sim 562 | UV16: Sim 563 | UW16: Sim 564 | UX16: Sim 565 | UY16: Sim 566 | UZ16: Sim 567 | VA16: Sim 568 | VB16: Sim 569 | VC16: Sim 570 | VD16: Sim 571 | VE16: Sim 572 | VF16: Sim 573 | VG16: Sim 574 | VH16: Sim 575 | VI16: Sim 576 | VJ16: Sim 577 | VK16: Sim 578 | VL16: Sim 579 | VM16: Sim 580 | VN16: Sim 581 | VO16: Sim 582 | VP16: Sim 583 | VQ16: Sim 584 | VR16: Sim 585 | VS16: Sim 586 | VT16: Sim 587 | VU16: Sim 588 | VV16: Sim 589 | VW16: Sim 590 | VX16: Sim 591 | VY16: Sim 592 | VZ16: Sim 593 | WA16: Sim 594 | WB16: Sim 595 | WC16: Sim 596 | WD16: Sim 597 | WE16: Sim 598 | WF16: Sim 599 | WG16: Sim 600 | WH16: Sim 601 | WI16: Sim 602 | WJ16: Sim 603 | WK16: Sim 604 | WL16: Sim 605 | WM16: Sim 606 | WN16: Sim 607 | WO16: Sim 608 | WP16: Sim 609 | WQ16: Sim 610 | WR16: Sim 611 | WS16: Sim 612 | WT16: Sim 613 | WU16: Sim 614 | WV16: Sim 615 | WW16: Sim 616 | WX16: Sim 617 | WY16: Sim 618 | WZ16: Sim 619 | XA16: Sim 620 | XB16: Sim 621 | XC16: Sim 622 | XD16: Sim 623 | XE16: Sim 624 | XF16: Sim 625 | XG16: Sim 626 | XH16: Sim 627 | XI16: Sim 628 | XJ16: Sim 629 | XK16: Sim 630 | XL16: Sim 631 | XM16: Sim 632 | XN16: Sim 633 | XO16: Sim 634 | XP16: Sim 635 | XQ16: Sim 636 | XR16: Sim 637 | XS16: Sim 638 | XT16: Sim 639 | XU16: Sim 640 | XV16: Sim 641 | XW16: Sim 642 | XX16: Sim 643 | XY16: Sim 644 | XZ16: Sim 645 | YA16: Sim 646 | YB16: Sim 647 | YC16: Sim 648 | YD16: Sim 649 | YE16: Sim 650 | YF16: Sim 651 | YG16: Sim 652 | YH16: Sim 653 | YI16: Sim 654 | YJ16: Sim 655 | YK16: Sim 656 | YL16: Sim 657 | YM16: Sim 658 | YN16: Sim 659 | YO16: Sim 660 | YP16: Sim 661 | YQ16: Sim 662 | YR16: Sim 663 | YS16: Sim 664 | YT16: Sim 665 | YU16: Sim 666 | YV16: Sim 667 | YW16: Sim 668 | YX16: Sim 669 | YY16: Sim 670 | YZ16: Sim 671 | ZA16: Sim 672 | ZB16: Sim 673 | ZC16: Sim 674 | ZD16: Sim 675 | ZE16: Sim 676 | ZF16: Sim 677 | ZG16: Sim 678 | ZH16: Sim 679 | ZI16: Sim 680 | ZJ16: Sim 681 | ZK16: Sim 682 | ZL16: Sim 683 | ZM16: Sim 684 | ZN16: Sim 685 | ZO16: Sim 686 | ZP16: Sim 687 | ZQ16: Sim 688 | ZR16: Sim 689 | ZS16: Sim 690 | ZT16: Sim 691 | ZU16: Sim 692 | ZV16: Sim 693 | ZW16: Sim 694 | ZX16: Sim 695 | ZY16: Sim 696 | ZZ16: Sim 697 | AAA16: Sim 698 | AAB16: Sim 699 | AAC16: Sim 700 | AAD16: Sim 701 | AAE16: Sim 702 | AAF16: Sim 703 | AAG16: Sim 704 | AAH16: Sim 705 | AAI16: Sim 706 | AAJ16: Sim 707 | AAK16: Sim 708 | AAL16: Sim 709 | AAM16: Sim 710 | AAN16: Sim 711 | AAO16: Sim 712 | AAP16: Sim 713 | AAQ16: Sim 714 | AAR16: Sim 715 | AAS16: Sim 716 | AAT16: Sim 717 | AAU16: Sim 718 | AAV16: Sim 719 | AAW16: Sim 720 | AAX16: Sim 721 | AAY16: Sim 722 | AAZ16: Sim 723 | ABA16: Sim 724 | ABB16: Sim 725 | ABC16: Sim 726 | ABD16: Sim 727 | ABE16: Sim 728 | ABF16: Sim 729 | ABG16: Sim 730 | ABH16: Sim 731 | ABI16: Sim 732 | ABJ16: Sim 733 | ABK16: Sim 734 | ABL16: Sim 735 | ABM16: Sim 736 | ABN16: Sim 737 | ABO16: Sim 738 | ABP16: Sim 739 | ABQ16: Sim 740 | ABR16: Sim 741 | ABS16: Sim 742 | ABT16: Sim 743 | ABU16: Sim 744 | ABV16: Sim 745 | ABW16: Sim 746 | ABX16: Sim 747 | ABY16: Sim 748 | ABZ16: Sim 749 | ACA16: Sim 750 | ACB16: Sim 751 | ACC16: Sim 752 | ACD16: Sim 753 | ACE16: Sim 754 | ACF16: Sim 755 | ACG16: Sim 756 | ACH16: Sim 757 | ACI16: Sim 758 | ACJ16: Sim 759 | ACK16: Sim 760 | ACL16: Sim 761 | ACM16: Sim 762 | ACN16: Sim 763 | ACO16: Sim 764 | ACP16: Sim 765 | ACQ16: Sim 766 | ACR16: Sim 767 | ACS16: Sim 768 | ACT16: Sim 769 | ACU16: Sim 770 | ACV16: Sim 771 | ACW16: Sim 772 | ACX16: Sim 773 | ACY16: Sim 774 | ACZ16: Sim 775 | ADA16: Sim 776 | ADB16: Sim 777 | ADC16: Sim 778 | ADD16: Sim 779 | ADE16: Sim 780 | ADF16: Sim 781 | ADG16: Sim 782 | ADH16: Sim 783 | ADI16: Sim 784 | ADJ16: Sim 785 | ADK16: Sim 786 | ADL16: Sim 787 | ADM16: Sim 788 | ADN16: Sim 789 | ADO16: Sim 790 | ADP16: Sim 791 | ADQ16: Sim 792 | ADR16: Sim 793 | ADS16: Sim 794 | ADT16: Sim 795 | ADU16: Sim 796 | ADV16: Sim 797 | ADW16: Sim 798 | ADX16: Sim 799 | ADY16: Sim 800 | ADZ16: Sim 801 | AEA16: Sim 802 | AEB16: Sim 803 | AEC16: Sim 804 | AED16: Sim 805 | AEE16: Sim 806 | AEF16: Sim 807 | AEG16: Sim 808 | AEH16: Sim 809 | AEI16: Sim 810 | AEJ16: Sim 811 | AEK16: Sim 812 | AEL16: Sim 813 | AEM16: Sim 814 | AEN16: Sim 815 | AEO16: Sim 816 | AEP16: Sim 817 | AEQ16: Sim 818 | AER16: Sim 819 | AES16: Sim 820 | AET16: Sim 821 | AEU16: Sim 822 | AEV16: Sim 823 | AEW16: Sim 824 | AEX16: Sim 825 | AEY16: Sim 826 | AEZ16: Sim 827 | AFA16: Sim 828 | AFB16: Sim 829 | AFC16: Sim 830 | AFD16: Sim 831 | AFE16: Sim 832 | AFF16: Sim 833 | AFG16: Sim 834 | AFH16: Sim 835 | AFI16: Sim 836 | AFJ16: Sim 837 | AFK16: Sim 838 | AFL16: Sim 839 | AFM16: Sim 840 | AFN16: Sim 841 | AFO16: Sim 842 | AFP16: Sim 843 | AFQ16: Sim 844 | AFR16: Sim 845 | AFS16: Sim 846 | AFT16: Sim 847 | AFU16: Sim 848 | AFV16: Sim 849 | AFW16: Sim 850 | AFX16: Sim 851 | AFY16: Sim 852 | AFZ16: Sim 853 | AGA16: Sim 854 | AGB16: Sim 855 | AGC16: Sim 856 | AGD16: Sim 857 | AGE16: Sim 858 | AGF16: Sim 859 | AGG16: Sim 860 | AGH16: Sim 861 | AGI16: Sim 862 | AGJ16: Sim 863 | AGK16: Sim 864 | AGL16: Sim 865 | AGM16: Sim 866 | AGN16: Sim 867 | AGO16: Sim 868 | AGP16: Sim 869 | AGQ16: Sim 870 | AGR16: Sim 871 | AGS16: Sim 872 | AGT16: Sim 873 | AGU16: Sim 874 | AGV16: Sim 875 | AGW16: Sim 876 | AGX16: Sim 877 | AGY16: Sim 878 | AGZ16: Sim 879 | AHA16: Sim 880 | AHB16: Sim 881 | AHC16: Sim 882 | AHD16: Sim 883 | AHE16: Sim 884 | AHF16: Sim 885 | AHG16: Sim 886 | AHH16: Sim 887 | AHI16: Sim 888 | AHJ16: Sim 889 | AHK16: Sim 890 | AHL16: Sim 891 | AHM16: Sim 892 | AHN16: Sim 893 | AHO16: Sim 894 | AHP16: Sim 895 | AHQ16: Sim 896 | AHR16: Sim 897 | AHS16: Sim 898 | AHT16: Sim 899 | AHU16: Sim 900 | AHV16: Sim 901 | AHW16: Sim 902 | AHX16: Sim 903 | AHY16: Sim 904 | AHZ16: Sim 905 | AIA16: Sim 906 | AIB16: Sim 907 | AIC16: Sim 908 | AID16: Sim 909 | AIE16: Sim 910 | AIF16: Sim 911 | AIG16: Sim 912 | AIH16: Sim 913 | AII16: Sim 914 | AIJ16: Sim 915 | AIK16: Sim 916 | AIL16: Sim 917 | AIM16: Sim 918 | AIN16: Sim 919 | AIO16: Sim 920 | AIP16: Sim 921 | AIQ16: Sim 922 | AIR16: Sim 923 | AIS16: Sim 924 | AIT16: Sim 925 | AIU16: Sim 926 | AIV16: Sim 927 | AIW16: Sim 928 | AIX16: Sim 929 | AIY16: Sim 930 | AIZ16: Sim 931 | AJA16: Sim 932 | AJB16: Sim 933 | AJC16: Sim 934 | AJD16: Sim 935 | AJE16: Sim 936 | AJF16: Sim 937 | AJG16: Sim 938 | AJH16: Sim 939 | AJI16: Sim 940 | AJJ16: Sim 941 | AJK16: Sim 942 | AJL16: Sim 943 | AJM16: Sim 944 | AJN16: Sim 945 | AJO16: Sim 946 | AJP16: Sim 947 | AJQ16: Sim 948 | AJR16: Sim 949 | AJS16: Sim 950 | AJT16: Sim 951 | AJU16: Sim 952 | AJV16: Sim 953 | AJW16: Sim 954 | AJX16: Sim 955 | AJY16: Sim 956 | AJZ16: Sim 957 | AKA16: Sim 958 | AKB16: Sim 959 | AKC16: Sim 960 | AKD16: Sim 961 | AKE16: Sim 962 | AKF16: Sim 963 | AKG16: Sim 964 | AKH16: Sim 965 | AKI16: Sim 966 | AKJ16: Sim 967 | AKK16: Sim 968 | AKL16: Sim 969 | AKM16: Sim 970 | AKN16: Sim 971 | AKO16: Sim 972 | AKP16: Sim 973 | AKQ16: Sim 974 | AKR16: Sim 975 | AKS16: Sim 976 | AKT16: Sim 977 | AKU16: Sim 978 | AKV16: Sim 979 | AKW16: Sim 980 | AKX16: Sim 981 | AKY16: Sim 982 | AKZ16: Sim 983 | ALA16: Sim 984 | ALB16: Sim 985 | ALC16: Sim 986 | ALD16: Sim 987 | ALE16: Sim 988 | ALF16: Sim 989 | ALG16: Sim 990 | ALH16: Sim 991 | ALI16: Sim 992 | ALJ16: Sim 993 | ALK16: Sim 994 | ALL16: Sim 995 | ALM16: Sim 996 | ALN16: Sim 997 | ALO16: Sim 998 | ALP16: Sim 999 | ALQ16: Sim 1000
D17: =AVERAGE(F17:ALQ17) -> 61.988811 | E17: 0 | F17: =$D$3 -> 61.988811 | G17: =$D$3 -> 61.988811 | H17: =$D$3 -> 61.988811 | I17: =$D$3 -> 61.988811 | J17: =$D$3 -> 61.988811 | K17: =$D$3 -> 61.988811 | L17: =$D$3 -> 61.988811 | M17: =$D$3 -> 61.988811 | ... ALQ17: =$D$3 -> 61.988811
C18: =D18/D17-1 -> 0.1230696 | D18: =AVERAGE(F18:ALQ18) -> 69.617749 | E18: 1 | F18: =F17*(1 + NORMINV(RAND(), $D$4, $D$5)) -> 3.7378556 | G18: =G17*(1 + NORMINV(RAND(), $D$4, $D$5)) -> 55.379572 | H18: =H17*(1 + NORMINV(RAND(), $D$4, $D$5)) -> 11.855439 | I18: =I17*(1 + NORMINV(RAND(), $D$4, $D$5)) -> 87.53097 | J18: =J17*(1 + NORMINV(RAND(), $D$4, $D$5)) -> 105.32628 | K18: =K17*(1 + NORMINV(RAND(), $D$4, $D$5)) -> 107.95501 | L18: =L17*(1 + NORMINV(RAND(), $D$4, $D$5)) -> 28.620617 | M18: =M17*(1 + NORMINV(RAND(), $D$4, $D$5)) -> 36.164975 | ... ALQ18: =ALQ17*(1 + NORMINV(RAND(), $D$4, $D$5)) -> 74.819774
C19: =D19/D18-1 -> 0.081306687 | D19: =AVERAGE(F19:ALQ19) -> 75.278138 | E19: 2 | F19: =F18*(1 + NORMINV(RAND(), $D$4, $D$5)) -> 5.2213745 | G19: =G18*(1 + NORMINV(RAND(), $D$4, $D$5)) -> 49.319177 | H19: =H18*(1 + NORMINV(RAND(), $D$4, $D$5)) -> 16.513025 | I19: =I18*(1 + NORMINV(RAND(), $D$4, $D$5)) -> 89.17238 | J19: =J18*(1 + NORMINV(RAND(), $D$4, $D$5)) -> 15.132096 | K19: =K18*(1 + NORMINV(RAND(), $D$4, $D$5)) -> 175.13633 | L19: =L18*(1 + NORMINV(RAND(), $D$4, $D$5)) -> 50.844684 | M19: =M18*(1 + NORMINV(RAND(), $D$4, $D$5)) -> 53.303428 | ... ALQ19: =ALQ18*(1 + NORMINV(RAND(), $D$4, $D$5)) -> 20.888487
C20: =D20/D19-1 -> 0.11215531 | D20: =AVERAGE(F20:ALQ20) -> 83.720981 | E20: 3 | F20: =F19*(1 + NORMINV(RAND(), $D$4, $D$5)) -> 2.6665887 | G20: =G19*(1 + NORMINV(RAND(), $D$4, $D$5)) -> 36.909537 | H20: =H19*(1 + NORMINV(RAND(), $D$4, $D$5)) -> 16.10334 | I20: =I19*(1 + NORMINV(RAND(), $D$4, $D$5)) -> 114.13663 | J20: =J19*(1 + NORMINV(RAND(), $D$4, $D$5)) -> 26.097897 | K20: =K19*(1 + NORMINV(RAND(), $D$4, $D$5)) -> 165.51597 | L20: =L19*(1 + NORMINV(RAND(), $D$4, $D$5)) -> 59.29773 | M20: =M19*(1 + NORMINV(RAND(), $D$4, $D$5)) -> 26.173131 | ... ALQ20: =ALQ19*(1 + NORMINV(RAND(), $D$4, $D$5)) -> 39.353543
C21: =D21/D20-1 -> 0.10042696 | D21: =AVERAGE(F21:ALQ21) -> 92.128824 | E21: 4 | F21: =F20*(1 + NORMINV(RAND(), $D$4, $D$5)) -> 5.2787851 | G21: =G20*(1 + NORMINV(RAND(), $D$4, $D$5)) -> 42.303001 | H21: =H20*(1 + NORMINV(RAND(), $D$4, $D$5)) -> 27.601113 | I21: =I20*(1 + NORMINV(RAND(), $D$4, $D$5)) -> 148.35148 | J21: =J20*(1 + NORMINV(RAND(), $D$4, $D$5)) -> 20.130418 | K21: =K20*(1 + NORMINV(RAND(), $D$4, $D$5)) -> 188.9621 | L21: =L20*(1 + NORMINV(RAND(), $D$4, $D$5)) -> 97.776232 | M21: =M20*(1 + NORMINV(RAND(), $D$4, $D$5)) -> 34.496522 | ... ALQ21: =ALQ20*(1 + NORMINV(RAND(), $D$4, $D$5)) -> 36.811112
C22: =D22/D21-1 -> 0.12891621 | D22: =AVERAGE(F22:ALQ22) -> 104.00572 | E22: 5 | F22: =F21*(1 + NORMINV(RAND(), $D$4, $D$5)) -> 6.3243123 | G22: =G21*(1 + NORMINV(RAND(), $D$4, $D$5)) -> 41.565376 | H22: =H21*(1 + NORMINV(RAND(), $D$4, $D$5)) -> 28.020758 | I22: =I21*(1 + NORMINV(RAND(), $D$4, $D$5)) -> 152.9936 | J22: =J21*(1 + NORMINV(RAND(), $D$4, $D$5)) -> 32.707477 | K22: =K21*(1 + NORMINV(RAND(), $D$4, $D$5)) -> 260.068 | L22: =L21*(1 + NORMINV(RAND(), $D$4, $D$5)) -> 164.1685 | M22: =M21*(1 + NORMINV(RAND(), $D$4, $D$5)) -> 17.514443 | ... ALQ22: =ALQ21*(1 + NORMINV(RAND(), $D$4, $D$5)) -> 33.449201
C23: =D23/D22-1 -> 0.079506187 | D23: =AVERAGE(F23:ALQ23) -> 112.27482 | E23: 6 | F23: =F22*(1 + NORMINV(RAND(), $D$4, $D$5)) -> 6.7305357 | G23: =G22*(1 + NORMINV(RAND(), $D$4, $D$5)) -> 63.531585 | H23: =H22*(1 + NORMINV(RAND(), $D$4, $D$5)) -> 32.497159 | I23: =I22*(1 + NORMINV(RAND(), $D$4, $D$5)) -> 200.91208 | J23: =J22*(1 + NORMINV(RAND(), $D$4, $D$5)) -> 36.206364 | K23: =K22*(1 + NORMINV(RAND(), $D$4, $D$5)) -> 173.11166 | L23: =L22*(1 + NORMINV(RAND(), $D$4, $D$5)) -> -12.851196 | M23: =M22*(1 + NORMINV(RAND(), $D$4, $D$5)) -> 21.538478 | ... ALQ23: =ALQ22*(1 + NORMINV(RAND(), $D$4, $D$5)) -> 45.408788
C24: =D24/D23-1 -> 0.095624698 | D24: =AVERAGE(F24:ALQ24) -> 123.01107 | E24: 7 | F24: =F23*(1 + NORMINV(RAND(), $D$4, $D$5)) -> 7.6079761 | G24: =G23*(1 + NORMINV(RAND(), $D$4, $D$5)) -> 90.645745 | H24: =H23*(1 + NORMINV(RAND(), $D$4, $D$5)) -> 71.125097 | I24: =I23*(1 + NORMINV(RAND(), $D$4, $D$5)) -> 174.10997 | J24: =J23*(1 + NORMINV(RAND(), $D$4, $D$5)) -> 20.16831 | K24: =K23*(1 + NORMINV(RAND(), $D$4, $D$5)) -> 263.98986 | L24: =L23*(1 + NORMINV(RAND(), $D$4, $D$5)) -> -15.86201 | M24: =M23*(1 + NORMINV(RAND(), $D$4, $D$5)) -> 33.063006 | ... ALQ24: =ALQ23*(1 + NORMINV(RAND(), $D$4, $D$5)) -> 72.1344
C25: =D25/D24-1 -> 0.12103913 | D25: =AVERAGE(F25:ALQ25) -> 137.90022 | E25: 8 | F25: =F24*(1 + NORMINV(RAND(), $D$4, $D$5)) -> 7.7869771 | G25: =G24*(1 + NORMINV(RAND(), $D$4, $D$5)) -> 181.3467 | H25: =H24*(1 + NORMINV(RAND(), $D$4, $D$5)) -> 67.278786 | I25: =I24*(1 + NORMINV(RAND(), $D$4, $D$5)) -> 212.35256 | J25: =J24*(1 + NORMINV(RAND(), $D$4, $D$5)) -> 30.869646 | K25: =K24*(1 + NORMINV(RAND(), $D$4, $D$5)) -> 134.79855 | L25: =L24*(1 + NORMINV(RAND(), $D$4, $D$5)) -> -23.731513 | M25: =M24*(1 + NORMINV(RAND(), $D$4, $D$5)) -> 36.985215 | ... ALQ25: =ALQ24*(1 + NORMINV(RAND(), $D$4, $D$5)) -> 68.723863
C26: =D26/D25-1 -> 0.12069031 | D26: =AVERAGE(F26:ALQ26) -> 154.54344 | E26: 9 | F26: =F25*(1 + NORMINV(RAND(), $D$4, $D$5)) -> 2.2647885 | G26: =G25*(1 + NORMINV(RAND(), $D$4, $D$5)) -> 249.53633 | H26: =H25*(1 + NORMINV(RAND(), $D$4, $D$5)) -> 107.61198 | I26: =I25*(1 + NORMINV(RAND(), $D$4, $D$5)) -> 196.76055 | J26: =J25*(1 + NORMINV(RAND(), $D$4, $D$5)) -> 38.77837 | K26: =K25*(1 + NORMINV(RAND(), $D$4, $D$5)) -> 205.31317 | L26: =L25*(1 + NORMINV(RAND(), $D$4, $D$5)) -> -32.602151 | M26: =M25*(1 + NORMINV(RAND(), $D$4, $D$5)) -> 8.3288542 | ... ALQ26: =ALQ25*(1 + NORMINV(RAND(), $D$4, $D$5)) -> 39.127779
C27: =D27/D26-1 -> 0.095280147 | D27: =AVERAGE(F27:ALQ27) -> 169.26836 | E27: 10 | F27: =F26*(1 + NORMINV(RAND(), $D$4, $D$5)) -> 2.83169 | G27: =G26*(1 + NORMINV(RAND(), $D$4, $D$5)) -> 266.84232 | H27: =H26*(1 + NORMINV(RAND(), $D$4, $D$5)) -> 179.06766 | I27: =I26*(1 + NORMINV(RAND(), $D$4, $D$5)) -> 113.4833 | J27: =J26*(1 + NORMINV(RAND(), $D$4, $D$5)) -> 19.863863 | K27: =K26*(1 + NORMINV(RAND(), $D$4, $D$5)) -> 171.8526 | L27: =L26*(1 + NORMINV(RAND(), $D$4, $D$5)) -> -47.185171 | M27: =M26*(1 + NORMINV(RAND(), $D$4, $D$5)) -> 9.6639047 | ... ALQ27: =ALQ26*(1 + NORMINV(RAND(), $D$4, $D$5)) -> 40.244471
